[2025-07-16T18:50:17.400+0000] {local_task_job_runner.py:123} INFO - ::group::Pre task execution logs
[2025-07-16T18:50:17.444+0000] {taskinstance.py:2614} INFO - Dependencies all met for dep_context=non-requeueable deps ti=<TaskInstance: turnstile_ml_pipeline.run_monitoring manual__2025-07-16T18:45:02+00:00 [queued]>
[2025-07-16T18:50:17.468+0000] {taskinstance.py:2614} INFO - Dependencies all met for dep_context=requeueable deps ti=<TaskInstance: turnstile_ml_pipeline.run_monitoring manual__2025-07-16T18:45:02+00:00 [queued]>
[2025-07-16T18:50:17.469+0000] {taskinstance.py:2867} INFO - Starting attempt 1 of 1
[2025-07-16T18:50:17.487+0000] {taskinstance.py:2890} INFO - Executing <Task(BashOperator): run_monitoring> on 2025-07-16 18:45:02+00:00
[2025-07-16T18:50:17.501+0000] {logging_mixin.py:190} WARNING - /home/***/.local/lib/python3.12/site-packages/***/task/task_runner/standard_task_runner.py:70 DeprecationWarning: This process (pid=506) is multi-threaded, use of fork() may lead to deadlocks in the child.
[2025-07-16T18:50:17.503+0000] {standard_task_runner.py:72} INFO - Started process 512 to run task
[2025-07-16T18:50:17.502+0000] {standard_task_runner.py:104} INFO - Running: ['***', 'tasks', 'run', 'turnstile_ml_pipeline', 'run_monitoring', 'manual__2025-07-16T18:45:02+00:00', '--job-id', '15', '--raw', '--subdir', 'DAGS_FOLDER/pipeline_dag.py', '--cfg-path', '/tmp/tmph8zy8704']
[2025-07-16T18:50:17.506+0000] {standard_task_runner.py:105} INFO - Job 15: Subtask run_monitoring
[2025-07-16T18:50:17.527+0000] {logging_mixin.py:190} WARNING - /home/***/.local/lib/python3.12/site-packages/***/settings.py:209 DeprecationWarning: The sql_alchemy_conn option in [core] has been moved to the sql_alchemy_conn option in [database] - the old setting has been used, but please update your config.
[2025-07-16T18:50:17.592+0000] {task_command.py:467} INFO - Running <TaskInstance: turnstile_ml_pipeline.run_monitoring manual__2025-07-16T18:45:02+00:00 [running]> on host 36b6cbfeb7c6
[2025-07-16T18:50:17.738+0000] {taskinstance.py:3134} INFO - Exporting env vars: AIRFLOW_CTX_DAG_OWNER='***' AIRFLOW_CTX_DAG_ID='turnstile_ml_pipeline' AIRFLOW_CTX_TASK_ID='run_monitoring' AIRFLOW_CTX_EXECUTION_DATE='2025-07-16T18:45:02+00:00' AIRFLOW_CTX_TRY_NUMBER='1' AIRFLOW_CTX_DAG_RUN_ID='manual__2025-07-16T18:45:02+00:00'
[2025-07-16T18:50:17.740+0000] {taskinstance.py:732} INFO - ::endgroup::
[2025-07-16T18:50:17.774+0000] {subprocess.py:78} INFO - Tmp dir root location: /tmp
[2025-07-16T18:50:17.776+0000] {subprocess.py:88} INFO - Running command: ['/usr/bin/bash', '-c', '\n            python /opt/***/pipeline/monitor.py                 --user ***                 --password ***                 --host postgres                 --port 5432                 --db_name ny_sub_turnstiles                 --predictions_table predictions                 --monitoring_table monitoring\n        ']
[2025-07-16T18:50:17.794+0000] {subprocess.py:99} INFO - Output:
[2025-07-16T18:50:20.273+0000] {subprocess.py:106} INFO - /opt/***/pipeline/monitor.py:59: DeprecationWarning: datetime.datetime.utcnow() is deprecated and scheduled for removal in a future version. Use timezone-aware objects to represent datetimes in UTC: datetime.datetime.now(datetime.UTC).
[2025-07-16T18:50:20.274+0000] {subprocess.py:106} INFO -   target_date = (datetime.utcnow() - timedelta(days=1)).date()
[2025-07-16T18:50:29.963+0000] {subprocess.py:106} INFO - [Monitoring] For date: 2025-07-15
[2025-07-16T18:50:29.964+0000] {subprocess.py:106} INFO - Traceback (most recent call last):
[2025-07-16T18:50:29.965+0000] {subprocess.py:106} INFO -   File "/opt/***/pipeline/monitor.py", line 107, in <module>
[2025-07-16T18:50:29.968+0000] {subprocess.py:106} INFO -     run_monitoring(
[2025-07-16T18:50:29.969+0000] {subprocess.py:106} INFO -   File "/opt/***/pipeline/monitor.py", line 63, in run_monitoring
[2025-07-16T18:50:29.971+0000] {subprocess.py:106} INFO -     df_actual = fetch_actual_data(str(target_date))
[2025-07-16T18:50:29.972+0000] {subprocess.py:106} INFO -                 ^^^^^^^^^^^^^^^^^^^^^^^^^^^^^^^^^^^
[2025-07-16T18:50:29.973+0000] {subprocess.py:106} INFO -   File "/opt/***/pipeline/monitor.py", line 15, in fetch_actual_data
[2025-07-16T18:50:29.975+0000] {subprocess.py:106} INFO -     df["date"] = pd.to_datetime(df["date"])
[2025-07-16T18:50:29.976+0000] {subprocess.py:106} INFO -                                 ~~^^^^^^^^
[2025-07-16T18:50:29.976+0000] {subprocess.py:106} INFO -   File "/home/***/.local/lib/python3.12/site-packages/pandas/core/frame.py", line 3893, in __getitem__
[2025-07-16T18:50:29.977+0000] {subprocess.py:106} INFO -     indexer = self.columns.get_loc(key)
[2025-07-16T18:50:29.978+0000] {subprocess.py:106} INFO -               ^^^^^^^^^^^^^^^^^^^^^^^^^
[2025-07-16T18:50:29.979+0000] {subprocess.py:106} INFO -   File "/home/***/.local/lib/python3.12/site-packages/pandas/core/indexes/range.py", line 418, in get_loc
[2025-07-16T18:50:29.979+0000] {subprocess.py:106} INFO -     raise KeyError(key)
[2025-07-16T18:50:29.980+0000] {subprocess.py:106} INFO - KeyError: 'date'
[2025-07-16T18:50:30.142+0000] {subprocess.py:110} INFO - Command exited with return code 1
[2025-07-16T18:50:30.156+0000] {taskinstance.py:3313} ERROR - Task failed with exception
Traceback (most recent call last):
  File "/home/airflow/.local/lib/python3.12/site-packages/airflow/models/taskinstance.py", line 768, in _execute_task
    result = _execute_callable(context=context, **execute_callable_kwargs)
             ^^^^^^^^^^^^^^^^^^^^^^^^^^^^^^^^^^^^^^^^^^^^^^^^^^^^^^^^^^^^^
  File "/home/airflow/.local/lib/python3.12/site-packages/airflow/models/taskinstance.py", line 734, in _execute_callable
    return ExecutionCallableRunner(
           ^^^^^^^^^^^^^^^^^^^^^^^^
  File "/home/airflow/.local/lib/python3.12/site-packages/airflow/utils/operator_helpers.py", line 252, in run
    return self.func(*args, **kwargs)
           ^^^^^^^^^^^^^^^^^^^^^^^^^^
  File "/home/airflow/.local/lib/python3.12/site-packages/airflow/models/baseoperator.py", line 424, in wrapper
    return func(self, *args, **kwargs)
           ^^^^^^^^^^^^^^^^^^^^^^^^^^^
  File "/home/airflow/.local/lib/python3.12/site-packages/airflow/operators/bash.py", line 276, in execute
    raise AirflowException(
airflow.exceptions.AirflowException: Bash command failed. The command returned a non-zero exit code 1.
[2025-07-16T18:50:30.162+0000] {taskinstance.py:1226} INFO - Marking task as FAILED. dag_id=turnstile_ml_pipeline, task_id=run_monitoring, run_id=manual__2025-07-16T18:45:02+00:00, execution_date=20250716T184502, start_date=20250716T185017, end_date=20250716T185030
[2025-07-16T18:50:30.201+0000] {taskinstance.py:341} INFO - ::group::Post task execution logs
[2025-07-16T18:50:30.202+0000] {standard_task_runner.py:124} ERROR - Failed to execute job 15 for task run_monitoring (Bash command failed. The command returned a non-zero exit code 1.; 512)
Traceback (most recent call last):
  File "/home/airflow/.local/lib/python3.12/site-packages/airflow/task/task_runner/standard_task_runner.py", line 117, in _start_by_fork
    ret = args.func(args, dag=self.dag)
          ^^^^^^^^^^^^^^^^^^^^^^^^^^^^^
  File "/home/airflow/.local/lib/python3.12/site-packages/airflow/cli/cli_config.py", line 49, in command
    return func(*args, **kwargs)
           ^^^^^^^^^^^^^^^^^^^^^
  File "/home/airflow/.local/lib/python3.12/site-packages/airflow/utils/cli.py", line 116, in wrapper
    return f(*args, **kwargs)
           ^^^^^^^^^^^^^^^^^^
  File "/home/airflow/.local/lib/python3.12/site-packages/airflow/cli/commands/task_command.py", line 483, in task_run
    task_return_code = _run_task_by_selected_method(args, _dag, ti)
                       ^^^^^^^^^^^^^^^^^^^^^^^^^^^^^^^^^^^^^^^^^^^^
  File "/home/airflow/.local/lib/python3.12/site-packages/airflow/cli/commands/task_command.py", line 256, in _run_task_by_selected_method
    return _run_raw_task(args, ti)
           ^^^^^^^^^^^^^^^^^^^^^^^
  File "/home/airflow/.local/lib/python3.12/site-packages/airflow/cli/commands/task_command.py", line 341, in _run_raw_task
    return ti._run_raw_task(
           ^^^^^^^^^^^^^^^^^
  File "/home/airflow/.local/lib/python3.12/site-packages/airflow/utils/session.py", line 97, in wrapper
    return func(*args, session=session, **kwargs)
           ^^^^^^^^^^^^^^^^^^^^^^^^^^^^^^^^^^^^^^
  File "/home/airflow/.local/lib/python3.12/site-packages/airflow/models/taskinstance.py", line 3006, in _run_raw_task
    return _run_raw_task(
           ^^^^^^^^^^^^^^
  File "/home/airflow/.local/lib/python3.12/site-packages/airflow/models/taskinstance.py", line 274, in _run_raw_task
    TaskInstance._execute_task_with_callbacks(
  File "/home/airflow/.local/lib/python3.12/site-packages/airflow/models/taskinstance.py", line 3161, in _execute_task_with_callbacks
    result = self._execute_task(context, task_orig)
             ^^^^^^^^^^^^^^^^^^^^^^^^^^^^^^^^^^^^^^
  File "/home/airflow/.local/lib/python3.12/site-packages/airflow/models/taskinstance.py", line 3185, in _execute_task
    return _execute_task(self, context, task_orig)
           ^^^^^^^^^^^^^^^^^^^^^^^^^^^^^^^^^^^^^^^
  File "/home/airflow/.local/lib/python3.12/site-packages/airflow/models/taskinstance.py", line 768, in _execute_task
    result = _execute_callable(context=context, **execute_callable_kwargs)
             ^^^^^^^^^^^^^^^^^^^^^^^^^^^^^^^^^^^^^^^^^^^^^^^^^^^^^^^^^^^^^
  File "/home/airflow/.local/lib/python3.12/site-packages/airflow/models/taskinstance.py", line 734, in _execute_callable
    return ExecutionCallableRunner(
           ^^^^^^^^^^^^^^^^^^^^^^^^
  File "/home/airflow/.local/lib/python3.12/site-packages/airflow/utils/operator_helpers.py", line 252, in run
    return self.func(*args, **kwargs)
           ^^^^^^^^^^^^^^^^^^^^^^^^^^
  File "/home/airflow/.local/lib/python3.12/site-packages/airflow/models/baseoperator.py", line 424, in wrapper
    return func(self, *args, **kwargs)
           ^^^^^^^^^^^^^^^^^^^^^^^^^^^
  File "/home/airflow/.local/lib/python3.12/site-packages/airflow/operators/bash.py", line 276, in execute
    raise AirflowException(
airflow.exceptions.AirflowException: Bash command failed. The command returned a non-zero exit code 1.
[2025-07-16T18:50:32.732+0000] {local_task_job_runner.py:266} INFO - Task exited with return code 1
[2025-07-16T18:50:32.759+0000] {taskinstance.py:3901} INFO - 0 downstream tasks scheduled from follow-on schedule check
[2025-07-16T18:50:32.762+0000] {local_task_job_runner.py:245} INFO - ::endgroup::
