[2025-07-13T14:13:40.509+0000] {local_task_job_runner.py:123} INFO - ::group::Pre task execution logs
[2025-07-13T14:13:40.567+0000] {taskinstance.py:2614} INFO - Dependencies all met for dep_context=non-requeueable deps ti=<TaskInstance: turnstile_ml_pipeline.tune_model manual__2025-07-13T14:12:32+00:00 [queued]>
[2025-07-13T14:13:40.585+0000] {taskinstance.py:2614} INFO - Dependencies all met for dep_context=requeueable deps ti=<TaskInstance: turnstile_ml_pipeline.tune_model manual__2025-07-13T14:12:32+00:00 [queued]>
[2025-07-13T14:13:40.586+0000] {taskinstance.py:2867} INFO - Starting attempt 1 of 1
[2025-07-13T14:13:40.621+0000] {taskinstance.py:2890} INFO - Executing <Task(BashOperator): tune_model> on 2025-07-13 14:12:32+00:00
[2025-07-13T14:13:40.654+0000] {standard_task_runner.py:104} INFO - Running: ['***', 'tasks', 'run', 'turnstile_ml_pipeline', 'tune_model', 'manual__2025-07-13T14:12:32+00:00', '--job-id', '7', '--raw', '--subdir', 'DAGS_FOLDER/pipeline_dag.py', '--cfg-path', '/tmp/tmp1zf7ei6o']
[2025-07-13T14:13:40.658+0000] {logging_mixin.py:190} WARNING - /home/***/.local/lib/python3.12/site-packages/***/task/task_runner/standard_task_runner.py:70 DeprecationWarning: This process (pid=125) is multi-threaded, use of fork() may lead to deadlocks in the child.
[2025-07-13T14:13:40.660+0000] {standard_task_runner.py:105} INFO - Job 7: Subtask tune_model
[2025-07-13T14:13:40.660+0000] {standard_task_runner.py:72} INFO - Started process 131 to run task
[2025-07-13T14:13:40.699+0000] {logging_mixin.py:190} WARNING - /home/***/.local/lib/python3.12/site-packages/***/settings.py:209 DeprecationWarning: The sql_alchemy_conn option in [core] has been moved to the sql_alchemy_conn option in [database] - the old setting has been used, but please update your config.
[2025-07-13T14:13:40.776+0000] {task_command.py:467} INFO - Running <TaskInstance: turnstile_ml_pipeline.tune_model manual__2025-07-13T14:12:32+00:00 [running]> on host 7bf41c76e92f
[2025-07-13T14:13:40.900+0000] {taskinstance.py:3134} INFO - Exporting env vars: AIRFLOW_CTX_DAG_OWNER='***' AIRFLOW_CTX_DAG_ID='turnstile_ml_pipeline' AIRFLOW_CTX_TASK_ID='tune_model' AIRFLOW_CTX_EXECUTION_DATE='2025-07-13T14:12:32+00:00' AIRFLOW_CTX_TRY_NUMBER='1' AIRFLOW_CTX_DAG_RUN_ID='manual__2025-07-13T14:12:32+00:00'
[2025-07-13T14:13:40.901+0000] {taskinstance.py:732} INFO - ::endgroup::
[2025-07-13T14:13:40.926+0000] {subprocess.py:78} INFO - Tmp dir root location: /tmp
[2025-07-13T14:13:40.928+0000] {subprocess.py:88} INFO - Running command: ['/usr/bin/bash', '-c', '\n            python /opt/***/pipeline/tune_model.py\n        ']
[2025-07-13T14:13:40.946+0000] {subprocess.py:99} INFO - Output:
[2025-07-13T14:13:47.308+0000] {subprocess.py:106} INFO - Traceback (most recent call last):
[2025-07-13T14:13:47.309+0000] {subprocess.py:106} INFO -   File "/home/***/.local/lib/python3.12/site-packages/sqlalchemy/engine/base.py", line 3371, in _wrap_pool_connect
[2025-07-13T14:13:47.311+0000] {subprocess.py:106} INFO -     return fn()
[2025-07-13T14:13:47.312+0000] {subprocess.py:106} INFO -            ^^^^
[2025-07-13T14:13:47.313+0000] {subprocess.py:106} INFO -   File "/home/***/.local/lib/python3.12/site-packages/sqlalchemy/pool/base.py", line 327, in connect
[2025-07-13T14:13:47.313+0000] {subprocess.py:106} INFO -     return _ConnectionFairy._checkout(self)
[2025-07-13T14:13:47.314+0000] {subprocess.py:106} INFO -            ^^^^^^^^^^^^^^^^^^^^^^^^^^^^^^^^
[2025-07-13T14:13:47.315+0000] {subprocess.py:106} INFO -   File "/home/***/.local/lib/python3.12/site-packages/sqlalchemy/pool/base.py", line 894, in _checkout
[2025-07-13T14:13:47.316+0000] {subprocess.py:106} INFO -     fairy = _ConnectionRecord.checkout(pool)
[2025-07-13T14:13:47.316+0000] {subprocess.py:106} INFO -             ^^^^^^^^^^^^^^^^^^^^^^^^^^^^^^^^
[2025-07-13T14:13:47.317+0000] {subprocess.py:106} INFO -   File "/home/***/.local/lib/python3.12/site-packages/sqlalchemy/pool/base.py", line 493, in checkout
[2025-07-13T14:13:47.317+0000] {subprocess.py:106} INFO -     rec = pool._do_get()
[2025-07-13T14:13:47.319+0000] {subprocess.py:106} INFO -           ^^^^^^^^^^^^^^
[2025-07-13T14:13:47.320+0000] {subprocess.py:106} INFO -   File "/home/***/.local/lib/python3.12/site-packages/sqlalchemy/pool/impl.py", line 145, in _do_get
[2025-07-13T14:13:47.321+0000] {subprocess.py:106} INFO -     with util.safe_reraise():
[2025-07-13T14:13:47.322+0000] {subprocess.py:106} INFO -          ^^^^^^^^^^^^^^^^^^^
[2025-07-13T14:13:47.323+0000] {subprocess.py:106} INFO -   File "/home/***/.local/lib/python3.12/site-packages/sqlalchemy/util/langhelpers.py", line 70, in __exit__
[2025-07-13T14:13:47.324+0000] {subprocess.py:106} INFO -     compat.raise_(
[2025-07-13T14:13:47.324+0000] {subprocess.py:106} INFO -   File "/home/***/.local/lib/python3.12/site-packages/sqlalchemy/util/compat.py", line 211, in raise_
[2025-07-13T14:13:47.325+0000] {subprocess.py:106} INFO -     raise exception
[2025-07-13T14:13:47.326+0000] {subprocess.py:106} INFO -   File "/home/***/.local/lib/python3.12/site-packages/sqlalchemy/pool/impl.py", line 143, in _do_get
[2025-07-13T14:13:47.327+0000] {subprocess.py:106} INFO -     return self._create_connection()
[2025-07-13T14:13:47.327+0000] {subprocess.py:106} INFO -            ^^^^^^^^^^^^^^^^^^^^^^^^^
[2025-07-13T14:13:47.328+0000] {subprocess.py:106} INFO -   File "/home/***/.local/lib/python3.12/site-packages/sqlalchemy/pool/base.py", line 273, in _create_connection
[2025-07-13T14:13:47.329+0000] {subprocess.py:106} INFO -     return _ConnectionRecord(self)
[2025-07-13T14:13:47.332+0000] {subprocess.py:106} INFO -            ^^^^^^^^^^^^^^^^^^^^^^^
[2025-07-13T14:13:47.333+0000] {subprocess.py:106} INFO -   File "/home/***/.local/lib/python3.12/site-packages/sqlalchemy/pool/base.py", line 388, in __init__
[2025-07-13T14:13:47.333+0000] {subprocess.py:106} INFO -     self.__connect()
[2025-07-13T14:13:47.335+0000] {subprocess.py:106} INFO -   File "/home/***/.local/lib/python3.12/site-packages/sqlalchemy/pool/base.py", line 690, in __connect
[2025-07-13T14:13:47.336+0000] {subprocess.py:106} INFO -     with util.safe_reraise():
[2025-07-13T14:13:47.337+0000] {subprocess.py:106} INFO -          ^^^^^^^^^^^^^^^^^^^
[2025-07-13T14:13:47.339+0000] {subprocess.py:106} INFO -   File "/home/***/.local/lib/python3.12/site-packages/sqlalchemy/util/langhelpers.py", line 70, in __exit__
[2025-07-13T14:13:47.340+0000] {subprocess.py:106} INFO -     compat.raise_(
[2025-07-13T14:13:47.341+0000] {subprocess.py:106} INFO -   File "/home/***/.local/lib/python3.12/site-packages/sqlalchemy/util/compat.py", line 211, in raise_
[2025-07-13T14:13:47.360+0000] {subprocess.py:106} INFO -     raise exception
[2025-07-13T14:13:47.361+0000] {subprocess.py:106} INFO -   File "/home/***/.local/lib/python3.12/site-packages/sqlalchemy/pool/base.py", line 686, in __connect
[2025-07-13T14:13:47.362+0000] {subprocess.py:106} INFO -     self.dbapi_connection = connection = pool._invoke_creator(self)
[2025-07-13T14:13:47.363+0000] {subprocess.py:106} INFO -                                          ^^^^^^^^^^^^^^^^^^^^^^^^^^
[2025-07-13T14:13:47.363+0000] {subprocess.py:106} INFO -   File "/home/***/.local/lib/python3.12/site-packages/sqlalchemy/engine/create.py", line 574, in connect
[2025-07-13T14:13:47.364+0000] {subprocess.py:106} INFO -     return dialect.connect(*cargs, **cparams)
[2025-07-13T14:13:47.364+0000] {subprocess.py:106} INFO -            ^^^^^^^^^^^^^^^^^^^^^^^^^^^^^^^^^^
[2025-07-13T14:13:47.365+0000] {subprocess.py:106} INFO -   File "/home/***/.local/lib/python3.12/site-packages/sqlalchemy/engine/default.py", line 598, in connect
[2025-07-13T14:13:47.366+0000] {subprocess.py:106} INFO -     return self.dbapi.connect(*cargs, **cparams)
[2025-07-13T14:13:47.366+0000] {subprocess.py:106} INFO -            ^^^^^^^^^^^^^^^^^^^^^^^^^^^^^^^^^^^^^
[2025-07-13T14:13:47.367+0000] {subprocess.py:106} INFO -   File "/home/***/.local/lib/python3.12/site-packages/psycopg2/__init__.py", line 122, in connect
[2025-07-13T14:13:47.368+0000] {subprocess.py:106} INFO -     conn = _connect(dsn, connection_factory=connection_factory, **kwasync)
[2025-07-13T14:13:47.369+0000] {subprocess.py:106} INFO -            ^^^^^^^^^^^^^^^^^^^^^^^^^^^^^^^^^^^^^^^^^^^^^^^^^^^^^^^^^^^^^^^
[2025-07-13T14:13:47.370+0000] {subprocess.py:106} INFO - psycopg2.OperationalError: connection to server at "localhost" (::1), port 5432 failed: Connection refused
[2025-07-13T14:13:47.372+0000] {subprocess.py:106} INFO - 	Is the server running on that host and accepting TCP/IP connections?
[2025-07-13T14:13:47.373+0000] {subprocess.py:106} INFO - connection to server at "localhost" (127.0.0.1), port 5432 failed: Connection refused
[2025-07-13T14:13:47.374+0000] {subprocess.py:106} INFO - 	Is the server running on that host and accepting TCP/IP connections?
[2025-07-13T14:13:47.374+0000] {subprocess.py:106} INFO - 
[2025-07-13T14:13:47.375+0000] {subprocess.py:106} INFO - 
[2025-07-13T14:13:47.376+0000] {subprocess.py:106} INFO - The above exception was the direct cause of the following exception:
[2025-07-13T14:13:47.376+0000] {subprocess.py:106} INFO - 
[2025-07-13T14:13:47.377+0000] {subprocess.py:106} INFO - Traceback (most recent call last):
[2025-07-13T14:13:47.377+0000] {subprocess.py:106} INFO -   File "/opt/***/pipeline/tune_model.py", line 28, in <module>
[2025-07-13T14:13:47.390+0000] {subprocess.py:106} INFO -     df = pd.read_sql(query, con=engine)
[2025-07-13T14:13:47.391+0000] {subprocess.py:106} INFO -          ^^^^^^^^^^^^^^^^^^^^^^^^^^^^^^
[2025-07-13T14:13:47.391+0000] {subprocess.py:106} INFO -   File "/home/***/.local/lib/python3.12/site-packages/pandas/io/sql.py", line 652, in read_sql
[2025-07-13T14:13:47.392+0000] {subprocess.py:106} INFO -     with pandasSQL_builder(con) as pandas_sql:
[2025-07-13T14:13:47.393+0000] {subprocess.py:106} INFO -          ^^^^^^^^^^^^^^^^^^^^^^
[2025-07-13T14:13:47.393+0000] {subprocess.py:106} INFO -   File "/home/***/.local/lib/python3.12/site-packages/pandas/io/sql.py", line 851, in pandasSQL_builder
[2025-07-13T14:13:47.400+0000] {subprocess.py:106} INFO -     return SQLDatabase(con, schema, need_transaction)
[2025-07-13T14:13:47.401+0000] {subprocess.py:106} INFO -            ^^^^^^^^^^^^^^^^^^^^^^^^^^^^^^^^^^^^^^^^^^
[2025-07-13T14:13:47.402+0000] {subprocess.py:106} INFO -   File "/home/***/.local/lib/python3.12/site-packages/pandas/io/sql.py", line 1576, in __init__
[2025-07-13T14:13:47.404+0000] {subprocess.py:106} INFO -     con = self.exit_stack.enter_context(con.connect())
[2025-07-13T14:13:47.405+0000] {subprocess.py:106} INFO -                                         ^^^^^^^^^^^^^
[2025-07-13T14:13:47.408+0000] {subprocess.py:106} INFO -   File "/home/***/.local/lib/python3.12/site-packages/sqlalchemy/engine/base.py", line 3325, in connect
[2025-07-13T14:13:47.409+0000] {subprocess.py:106} INFO -     return self._connection_cls(self, close_with_result=close_with_result)
[2025-07-13T14:13:47.410+0000] {subprocess.py:106} INFO -            ^^^^^^^^^^^^^^^^^^^^^^^^^^^^^^^^^^^^^^^^^^^^^^^^^^^^^^^^^^^^^^^
[2025-07-13T14:13:47.410+0000] {subprocess.py:106} INFO -   File "/home/***/.local/lib/python3.12/site-packages/sqlalchemy/engine/base.py", line 96, in __init__
[2025-07-13T14:13:47.411+0000] {subprocess.py:106} INFO -     else engine.raw_connection()
[2025-07-13T14:13:47.412+0000] {subprocess.py:106} INFO -          ^^^^^^^^^^^^^^^^^^^^^^^
[2025-07-13T14:13:47.413+0000] {subprocess.py:106} INFO -   File "/home/***/.local/lib/python3.12/site-packages/sqlalchemy/engine/base.py", line 3404, in raw_connection
[2025-07-13T14:13:47.413+0000] {subprocess.py:106} INFO -     return self._wrap_pool_connect(self.pool.connect, _connection)
[2025-07-13T14:13:47.420+0000] {subprocess.py:106} INFO -            ^^^^^^^^^^^^^^^^^^^^^^^^^^^^^^^^^^^^^^^^^^^^^^^^^^^^^^^
[2025-07-13T14:13:47.421+0000] {subprocess.py:106} INFO -   File "/home/***/.local/lib/python3.12/site-packages/sqlalchemy/engine/base.py", line 3374, in _wrap_pool_connect
[2025-07-13T14:13:47.422+0000] {subprocess.py:106} INFO -     Connection._handle_dbapi_exception_noconnection(
[2025-07-13T14:13:47.422+0000] {subprocess.py:106} INFO -   File "/home/***/.local/lib/python3.12/site-packages/sqlalchemy/engine/base.py", line 2208, in _handle_dbapi_exception_noconnection
[2025-07-13T14:13:47.423+0000] {subprocess.py:106} INFO -     util.raise_(
[2025-07-13T14:13:47.424+0000] {subprocess.py:106} INFO -   File "/home/***/.local/lib/python3.12/site-packages/sqlalchemy/util/compat.py", line 211, in raise_
[2025-07-13T14:13:47.424+0000] {subprocess.py:106} INFO -     raise exception
[2025-07-13T14:13:47.425+0000] {subprocess.py:106} INFO -   File "/home/***/.local/lib/python3.12/site-packages/sqlalchemy/engine/base.py", line 3371, in _wrap_pool_connect
[2025-07-13T14:13:47.426+0000] {subprocess.py:106} INFO -     return fn()
[2025-07-13T14:13:47.426+0000] {subprocess.py:106} INFO -            ^^^^
[2025-07-13T14:13:47.427+0000] {subprocess.py:106} INFO -   File "/home/***/.local/lib/python3.12/site-packages/sqlalchemy/pool/base.py", line 327, in connect
[2025-07-13T14:13:47.428+0000] {subprocess.py:106} INFO -     return _ConnectionFairy._checkout(self)
[2025-07-13T14:13:47.428+0000] {subprocess.py:106} INFO -            ^^^^^^^^^^^^^^^^^^^^^^^^^^^^^^^^
[2025-07-13T14:13:47.429+0000] {subprocess.py:106} INFO -   File "/home/***/.local/lib/python3.12/site-packages/sqlalchemy/pool/base.py", line 894, in _checkout
[2025-07-13T14:13:47.430+0000] {subprocess.py:106} INFO -     fairy = _ConnectionRecord.checkout(pool)
[2025-07-13T14:13:47.440+0000] {subprocess.py:106} INFO -             ^^^^^^^^^^^^^^^^^^^^^^^^^^^^^^^^
[2025-07-13T14:13:47.440+0000] {subprocess.py:106} INFO -   File "/home/***/.local/lib/python3.12/site-packages/sqlalchemy/pool/base.py", line 493, in checkout
[2025-07-13T14:13:47.441+0000] {subprocess.py:106} INFO -     rec = pool._do_get()
[2025-07-13T14:13:47.442+0000] {subprocess.py:106} INFO -           ^^^^^^^^^^^^^^
[2025-07-13T14:13:47.442+0000] {subprocess.py:106} INFO -   File "/home/***/.local/lib/python3.12/site-packages/sqlalchemy/pool/impl.py", line 145, in _do_get
[2025-07-13T14:13:47.443+0000] {subprocess.py:106} INFO -     with util.safe_reraise():
[2025-07-13T14:13:47.443+0000] {subprocess.py:106} INFO -          ^^^^^^^^^^^^^^^^^^^
[2025-07-13T14:13:47.444+0000] {subprocess.py:106} INFO -   File "/home/***/.local/lib/python3.12/site-packages/sqlalchemy/util/langhelpers.py", line 70, in __exit__
[2025-07-13T14:13:47.444+0000] {subprocess.py:106} INFO -     compat.raise_(
[2025-07-13T14:13:47.445+0000] {subprocess.py:106} INFO -   File "/home/***/.local/lib/python3.12/site-packages/sqlalchemy/util/compat.py", line 211, in raise_
[2025-07-13T14:13:47.445+0000] {subprocess.py:106} INFO -     raise exception
[2025-07-13T14:13:47.446+0000] {subprocess.py:106} INFO -   File "/home/***/.local/lib/python3.12/site-packages/sqlalchemy/pool/impl.py", line 143, in _do_get
[2025-07-13T14:13:47.448+0000] {subprocess.py:106} INFO -     return self._create_connection()
[2025-07-13T14:13:47.449+0000] {subprocess.py:106} INFO -            ^^^^^^^^^^^^^^^^^^^^^^^^^
[2025-07-13T14:13:47.450+0000] {subprocess.py:106} INFO -   File "/home/***/.local/lib/python3.12/site-packages/sqlalchemy/pool/base.py", line 273, in _create_connection
[2025-07-13T14:13:47.450+0000] {subprocess.py:106} INFO -     return _ConnectionRecord(self)
[2025-07-13T14:13:47.451+0000] {subprocess.py:106} INFO -            ^^^^^^^^^^^^^^^^^^^^^^^
[2025-07-13T14:13:47.453+0000] {subprocess.py:106} INFO -   File "/home/***/.local/lib/python3.12/site-packages/sqlalchemy/pool/base.py", line 388, in __init__
[2025-07-13T14:13:47.454+0000] {subprocess.py:106} INFO -     self.__connect()
[2025-07-13T14:13:47.455+0000] {subprocess.py:106} INFO -   File "/home/***/.local/lib/python3.12/site-packages/sqlalchemy/pool/base.py", line 690, in __connect
[2025-07-13T14:13:47.456+0000] {subprocess.py:106} INFO -     with util.safe_reraise():
[2025-07-13T14:13:47.457+0000] {subprocess.py:106} INFO -          ^^^^^^^^^^^^^^^^^^^
[2025-07-13T14:13:47.458+0000] {subprocess.py:106} INFO -   File "/home/***/.local/lib/python3.12/site-packages/sqlalchemy/util/langhelpers.py", line 70, in __exit__
[2025-07-13T14:13:47.458+0000] {subprocess.py:106} INFO -     compat.raise_(
[2025-07-13T14:13:47.459+0000] {subprocess.py:106} INFO -   File "/home/***/.local/lib/python3.12/site-packages/sqlalchemy/util/compat.py", line 211, in raise_
[2025-07-13T14:13:47.460+0000] {subprocess.py:106} INFO -     raise exception
[2025-07-13T14:13:47.461+0000] {subprocess.py:106} INFO -   File "/home/***/.local/lib/python3.12/site-packages/sqlalchemy/pool/base.py", line 686, in __connect
[2025-07-13T14:13:47.461+0000] {subprocess.py:106} INFO -     self.dbapi_connection = connection = pool._invoke_creator(self)
[2025-07-13T14:13:47.462+0000] {subprocess.py:106} INFO -                                          ^^^^^^^^^^^^^^^^^^^^^^^^^^
[2025-07-13T14:13:47.470+0000] {subprocess.py:106} INFO -   File "/home/***/.local/lib/python3.12/site-packages/sqlalchemy/engine/create.py", line 574, in connect
[2025-07-13T14:13:47.471+0000] {subprocess.py:106} INFO -     return dialect.connect(*cargs, **cparams)
[2025-07-13T14:13:47.472+0000] {subprocess.py:106} INFO -            ^^^^^^^^^^^^^^^^^^^^^^^^^^^^^^^^^^
[2025-07-13T14:13:47.473+0000] {subprocess.py:106} INFO -   File "/home/***/.local/lib/python3.12/site-packages/sqlalchemy/engine/default.py", line 598, in connect
[2025-07-13T14:13:47.480+0000] {subprocess.py:106} INFO -     return self.dbapi.connect(*cargs, **cparams)
[2025-07-13T14:13:47.481+0000] {subprocess.py:106} INFO -            ^^^^^^^^^^^^^^^^^^^^^^^^^^^^^^^^^^^^^
[2025-07-13T14:13:47.482+0000] {subprocess.py:106} INFO -   File "/home/***/.local/lib/python3.12/site-packages/psycopg2/__init__.py", line 122, in connect
[2025-07-13T14:13:47.482+0000] {subprocess.py:106} INFO -     conn = _connect(dsn, connection_factory=connection_factory, **kwasync)
[2025-07-13T14:13:47.483+0000] {subprocess.py:106} INFO -            ^^^^^^^^^^^^^^^^^^^^^^^^^^^^^^^^^^^^^^^^^^^^^^^^^^^^^^^^^^^^^^^
[2025-07-13T14:13:47.484+0000] {subprocess.py:106} INFO - sqlalchemy.exc.OperationalError: (psycopg2.OperationalError) connection to server at "localhost" (::1), port 5432 failed: Connection refused
[2025-07-13T14:13:47.490+0000] {subprocess.py:106} INFO - 	Is the server running on that host and accepting TCP/IP connections?
[2025-07-13T14:13:47.491+0000] {subprocess.py:106} INFO - connection to server at "localhost" (127.0.0.1), port 5432 failed: Connection refused
[2025-07-13T14:13:47.492+0000] {subprocess.py:106} INFO - 	Is the server running on that host and accepting TCP/IP connections?
[2025-07-13T14:13:47.493+0000] {subprocess.py:106} INFO - 
[2025-07-13T14:13:47.493+0000] {subprocess.py:106} INFO - (Background on this error at: https://sqlalche.me/e/14/e3q8)
[2025-07-13T14:13:47.951+0000] {subprocess.py:110} INFO - Command exited with return code 1
[2025-07-13T14:13:47.967+0000] {taskinstance.py:3313} ERROR - Task failed with exception
Traceback (most recent call last):
  File "/home/airflow/.local/lib/python3.12/site-packages/airflow/models/taskinstance.py", line 768, in _execute_task
    result = _execute_callable(context=context, **execute_callable_kwargs)
             ^^^^^^^^^^^^^^^^^^^^^^^^^^^^^^^^^^^^^^^^^^^^^^^^^^^^^^^^^^^^^
  File "/home/airflow/.local/lib/python3.12/site-packages/airflow/models/taskinstance.py", line 734, in _execute_callable
    return ExecutionCallableRunner(
           ^^^^^^^^^^^^^^^^^^^^^^^^
  File "/home/airflow/.local/lib/python3.12/site-packages/airflow/utils/operator_helpers.py", line 252, in run
    return self.func(*args, **kwargs)
           ^^^^^^^^^^^^^^^^^^^^^^^^^^
  File "/home/airflow/.local/lib/python3.12/site-packages/airflow/models/baseoperator.py", line 424, in wrapper
    return func(self, *args, **kwargs)
           ^^^^^^^^^^^^^^^^^^^^^^^^^^^
  File "/home/airflow/.local/lib/python3.12/site-packages/airflow/operators/bash.py", line 276, in execute
    raise AirflowException(
airflow.exceptions.AirflowException: Bash command failed. The command returned a non-zero exit code 1.
[2025-07-13T14:13:47.979+0000] {taskinstance.py:1226} INFO - Marking task as FAILED. dag_id=turnstile_ml_pipeline, task_id=tune_model, run_id=manual__2025-07-13T14:12:32+00:00, execution_date=20250713T141232, start_date=20250713T141340, end_date=20250713T141347
[2025-07-13T14:13:48.030+0000] {taskinstance.py:341} INFO - ::group::Post task execution logs
[2025-07-13T14:13:48.031+0000] {standard_task_runner.py:124} ERROR - Failed to execute job 7 for task tune_model (Bash command failed. The command returned a non-zero exit code 1.; 131)
Traceback (most recent call last):
  File "/home/airflow/.local/lib/python3.12/site-packages/airflow/task/task_runner/standard_task_runner.py", line 117, in _start_by_fork
    ret = args.func(args, dag=self.dag)
          ^^^^^^^^^^^^^^^^^^^^^^^^^^^^^
  File "/home/airflow/.local/lib/python3.12/site-packages/airflow/cli/cli_config.py", line 49, in command
    return func(*args, **kwargs)
           ^^^^^^^^^^^^^^^^^^^^^
  File "/home/airflow/.local/lib/python3.12/site-packages/airflow/utils/cli.py", line 116, in wrapper
    return f(*args, **kwargs)
           ^^^^^^^^^^^^^^^^^^
  File "/home/airflow/.local/lib/python3.12/site-packages/airflow/cli/commands/task_command.py", line 483, in task_run
    task_return_code = _run_task_by_selected_method(args, _dag, ti)
                       ^^^^^^^^^^^^^^^^^^^^^^^^^^^^^^^^^^^^^^^^^^^^
  File "/home/airflow/.local/lib/python3.12/site-packages/airflow/cli/commands/task_command.py", line 256, in _run_task_by_selected_method
    return _run_raw_task(args, ti)
           ^^^^^^^^^^^^^^^^^^^^^^^
  File "/home/airflow/.local/lib/python3.12/site-packages/airflow/cli/commands/task_command.py", line 341, in _run_raw_task
    return ti._run_raw_task(
           ^^^^^^^^^^^^^^^^^
  File "/home/airflow/.local/lib/python3.12/site-packages/airflow/utils/session.py", line 97, in wrapper
    return func(*args, session=session, **kwargs)
           ^^^^^^^^^^^^^^^^^^^^^^^^^^^^^^^^^^^^^^
  File "/home/airflow/.local/lib/python3.12/site-packages/airflow/models/taskinstance.py", line 3006, in _run_raw_task
    return _run_raw_task(
           ^^^^^^^^^^^^^^
  File "/home/airflow/.local/lib/python3.12/site-packages/airflow/models/taskinstance.py", line 274, in _run_raw_task
    TaskInstance._execute_task_with_callbacks(
  File "/home/airflow/.local/lib/python3.12/site-packages/airflow/models/taskinstance.py", line 3161, in _execute_task_with_callbacks
    result = self._execute_task(context, task_orig)
             ^^^^^^^^^^^^^^^^^^^^^^^^^^^^^^^^^^^^^^
  File "/home/airflow/.local/lib/python3.12/site-packages/airflow/models/taskinstance.py", line 3185, in _execute_task
    return _execute_task(self, context, task_orig)
           ^^^^^^^^^^^^^^^^^^^^^^^^^^^^^^^^^^^^^^^
  File "/home/airflow/.local/lib/python3.12/site-packages/airflow/models/taskinstance.py", line 768, in _execute_task
    result = _execute_callable(context=context, **execute_callable_kwargs)
             ^^^^^^^^^^^^^^^^^^^^^^^^^^^^^^^^^^^^^^^^^^^^^^^^^^^^^^^^^^^^^
  File "/home/airflow/.local/lib/python3.12/site-packages/airflow/models/taskinstance.py", line 734, in _execute_callable
    return ExecutionCallableRunner(
           ^^^^^^^^^^^^^^^^^^^^^^^^
  File "/home/airflow/.local/lib/python3.12/site-packages/airflow/utils/operator_helpers.py", line 252, in run
    return self.func(*args, **kwargs)
           ^^^^^^^^^^^^^^^^^^^^^^^^^^
  File "/home/airflow/.local/lib/python3.12/site-packages/airflow/models/baseoperator.py", line 424, in wrapper
    return func(self, *args, **kwargs)
           ^^^^^^^^^^^^^^^^^^^^^^^^^^^
  File "/home/airflow/.local/lib/python3.12/site-packages/airflow/operators/bash.py", line 276, in execute
    raise AirflowException(
airflow.exceptions.AirflowException: Bash command failed. The command returned a non-zero exit code 1.
[2025-07-13T14:13:48.051+0000] {local_task_job_runner.py:266} INFO - Task exited with return code 1
[2025-07-13T14:13:48.107+0000] {taskinstance.py:3901} INFO - 0 downstream tasks scheduled from follow-on schedule check
[2025-07-13T14:13:48.127+0000] {local_task_job_runner.py:245} INFO - ::endgroup::
