[2025-07-14T18:24:38.761+0000] {local_task_job_runner.py:123} INFO - ::group::Pre task execution logs
[2025-07-14T18:24:38.801+0000] {taskinstance.py:2614} INFO - Dependencies all met for dep_context=non-requeueable deps ti=<TaskInstance: turnstile_ml_pipeline.run_inference scheduled__2025-07-13T00:00:00+00:00 [queued]>
[2025-07-14T18:24:38.822+0000] {taskinstance.py:2614} INFO - Dependencies all met for dep_context=requeueable deps ti=<TaskInstance: turnstile_ml_pipeline.run_inference scheduled__2025-07-13T00:00:00+00:00 [queued]>
[2025-07-14T18:24:38.823+0000] {taskinstance.py:2867} INFO - Starting attempt 6 of 6
[2025-07-14T18:24:38.847+0000] {taskinstance.py:2890} INFO - Executing <Task(BashOperator): run_inference> on 2025-07-13 00:00:00+00:00
[2025-07-14T18:24:38.864+0000] {logging_mixin.py:190} WARNING - /home/***/.local/lib/python3.12/site-packages/***/task/task_runner/standard_task_runner.py:70 DeprecationWarning: This process (pid=1928) is multi-threaded, use of fork() may lead to deadlocks in the child.
[2025-07-14T18:24:38.867+0000] {standard_task_runner.py:72} INFO - Started process 1934 to run task
[2025-07-14T18:24:38.866+0000] {standard_task_runner.py:104} INFO - Running: ['***', 'tasks', 'run', 'turnstile_ml_pipeline', 'run_inference', 'scheduled__2025-07-13T00:00:00+00:00', '--job-id', '35', '--raw', '--subdir', 'DAGS_FOLDER/pipeline_dag.py', '--cfg-path', '/tmp/tmp4yf50ky4']
[2025-07-14T18:24:38.872+0000] {standard_task_runner.py:105} INFO - Job 35: Subtask run_inference
[2025-07-14T18:24:38.900+0000] {logging_mixin.py:190} WARNING - /home/***/.local/lib/python3.12/site-packages/***/settings.py:209 DeprecationWarning: The sql_alchemy_conn option in [core] has been moved to the sql_alchemy_conn option in [database] - the old setting has been used, but please update your config.
[2025-07-14T18:24:38.977+0000] {task_command.py:467} INFO - Running <TaskInstance: turnstile_ml_pipeline.run_inference scheduled__2025-07-13T00:00:00+00:00 [running]> on host d84888688479
[2025-07-14T18:24:38.981+0000] {logging_mixin.py:190} WARNING - /home/***/.local/lib/python3.12/site-packages/***/settings.py:470 DeprecationWarning: The sql_alchemy_conn option in [core] has been moved to the sql_alchemy_conn option in [database] - the old setting has been used, but please update your config.
[2025-07-14T18:24:39.149+0000] {taskinstance.py:3134} INFO - Exporting env vars: AIRFLOW_CTX_DAG_OWNER='***' AIRFLOW_CTX_DAG_ID='turnstile_ml_pipeline' AIRFLOW_CTX_TASK_ID='run_inference' AIRFLOW_CTX_EXECUTION_DATE='2025-07-13T00:00:00+00:00' AIRFLOW_CTX_TRY_NUMBER='6' AIRFLOW_CTX_DAG_RUN_ID='scheduled__2025-07-13T00:00:00+00:00'
[2025-07-14T18:24:39.151+0000] {taskinstance.py:732} INFO - ::endgroup::
[2025-07-14T18:24:39.181+0000] {subprocess.py:78} INFO - Tmp dir root location: /tmp
[2025-07-14T18:24:39.183+0000] {subprocess.py:88} INFO - Running command: ['/usr/bin/bash', '-c', '\n            python /opt/***/pipeline/inference.py                 --user ***                 --password ***                 --host postgres                 --port 5432                 --db_name ny_sub_turnstiles                 --inference_table inference_features                 --predictions_table predictions\n        ']
[2025-07-14T18:24:39.208+0000] {subprocess.py:99} INFO - Output:
[2025-07-14T18:24:51.791+0000] {subprocess.py:106} INFO - Traceback (most recent call last):
[2025-07-14T18:24:51.793+0000] {subprocess.py:106} INFO -   File "/opt/***/pipeline/inference.py", line 56, in <module>
[2025-07-14T18:24:51.798+0000] {subprocess.py:106} INFO -     predict_and_save(
[2025-07-14T18:24:51.801+0000] {subprocess.py:106} INFO -   File "/opt/***/pipeline/inference.py", line 29, in predict_and_save
[2025-07-14T18:24:51.812+0000] {subprocess.py:106} INFO -     dmat = xgb.DMatrix(df_pred[FEATURES], enable_categorical=True )
[2025-07-14T18:24:51.824+0000] {subprocess.py:106} INFO -            ^^^^^^^^^^^^^^^^^^^^^^^^^^^^^^^^^^^^^^^^^^^^^^^^^^^^^^^^
[2025-07-14T18:24:51.825+0000] {subprocess.py:106} INFO -   File "/home/***/.local/lib/python3.12/site-packages/xgboost/core.py", line 620, in inner_f
[2025-07-14T18:24:51.827+0000] {subprocess.py:106} INFO -     return func(**kwargs)
[2025-07-14T18:24:51.829+0000] {subprocess.py:106} INFO -            ^^^^^^^^^^^^^^
[2025-07-14T18:24:51.830+0000] {subprocess.py:106} INFO -   File "/home/***/.local/lib/python3.12/site-packages/xgboost/core.py", line 743, in __init__
[2025-07-14T18:24:51.843+0000] {subprocess.py:106} INFO -     handle, feature_names, feature_types = dispatch_data_backend(
[2025-07-14T18:24:51.845+0000] {subprocess.py:106} INFO -                                            ^^^^^^^^^^^^^^^^^^^^^^
[2025-07-14T18:24:51.846+0000] {subprocess.py:106} INFO -   File "/home/***/.local/lib/python3.12/site-packages/xgboost/data.py", line 970, in dispatch_data_backend
[2025-07-14T18:24:51.847+0000] {subprocess.py:106} INFO -     return _from_pandas_df(data, enable_categorical, missing, threads,
[2025-07-14T18:24:51.848+0000] {subprocess.py:106} INFO -            ^^^^^^^^^^^^^^^^^^^^^^^^^^^^^^^^^^^^^^^^^^^^^^^^^^^^^^^^^^^
[2025-07-14T18:24:51.849+0000] {subprocess.py:106} INFO -   File "/home/***/.local/lib/python3.12/site-packages/xgboost/data.py", line 417, in _from_pandas_df
[2025-07-14T18:24:51.850+0000] {subprocess.py:106} INFO -     data, feature_names, feature_types = _transform_pandas_df(
[2025-07-14T18:24:51.852+0000] {subprocess.py:106} INFO -                                          ^^^^^^^^^^^^^^^^^^^^^
[2025-07-14T18:24:51.864+0000] {subprocess.py:106} INFO -   File "/home/***/.local/lib/python3.12/site-packages/xgboost/data.py", line 391, in _transform_pandas_df
[2025-07-14T18:24:51.865+0000] {subprocess.py:106} INFO -     _invalid_dataframe_dtype(data)
[2025-07-14T18:24:51.866+0000] {subprocess.py:106} INFO -   File "/home/***/.local/lib/python3.12/site-packages/xgboost/data.py", line 283, in _invalid_dataframe_dtype
[2025-07-14T18:24:51.867+0000] {subprocess.py:106} INFO -     raise ValueError(msg)
[2025-07-14T18:24:51.868+0000] {subprocess.py:106} INFO - ValueError: DataFrame.dtypes for data must be int, float, bool or category. When categorical type is supplied, The experimental DMatrix parameter`enable_categorical` must be set to `True`.  Invalid columns:entries_4h_last_week: object, group_key: category
[2025-07-14T18:24:52.690+0000] {subprocess.py:110} INFO - Command exited with return code 1
[2025-07-14T18:24:52.761+0000] {taskinstance.py:3313} ERROR - Task failed with exception
Traceback (most recent call last):
  File "/home/airflow/.local/lib/python3.12/site-packages/airflow/models/taskinstance.py", line 768, in _execute_task
    result = _execute_callable(context=context, **execute_callable_kwargs)
             ^^^^^^^^^^^^^^^^^^^^^^^^^^^^^^^^^^^^^^^^^^^^^^^^^^^^^^^^^^^^^
  File "/home/airflow/.local/lib/python3.12/site-packages/airflow/models/taskinstance.py", line 734, in _execute_callable
    return ExecutionCallableRunner(
           ^^^^^^^^^^^^^^^^^^^^^^^^
  File "/home/airflow/.local/lib/python3.12/site-packages/airflow/utils/operator_helpers.py", line 252, in run
    return self.func(*args, **kwargs)
           ^^^^^^^^^^^^^^^^^^^^^^^^^^
  File "/home/airflow/.local/lib/python3.12/site-packages/airflow/models/baseoperator.py", line 424, in wrapper
    return func(self, *args, **kwargs)
           ^^^^^^^^^^^^^^^^^^^^^^^^^^^
  File "/home/airflow/.local/lib/python3.12/site-packages/airflow/operators/bash.py", line 276, in execute
    raise AirflowException(
airflow.exceptions.AirflowException: Bash command failed. The command returned a non-zero exit code 1.
[2025-07-14T18:24:52.771+0000] {taskinstance.py:1226} INFO - Marking task as FAILED. dag_id=turnstile_ml_pipeline, task_id=run_inference, run_id=scheduled__2025-07-13T00:00:00+00:00, execution_date=20250713T000000, start_date=20250714T182438, end_date=20250714T182452
[2025-07-14T18:24:52.863+0000] {taskinstance.py:341} INFO - ::group::Post task execution logs
[2025-07-14T18:24:52.865+0000] {standard_task_runner.py:124} ERROR - Failed to execute job 35 for task run_inference (Bash command failed. The command returned a non-zero exit code 1.; 1934)
Traceback (most recent call last):
  File "/home/airflow/.local/lib/python3.12/site-packages/airflow/task/task_runner/standard_task_runner.py", line 117, in _start_by_fork
    ret = args.func(args, dag=self.dag)
          ^^^^^^^^^^^^^^^^^^^^^^^^^^^^^
  File "/home/airflow/.local/lib/python3.12/site-packages/airflow/cli/cli_config.py", line 49, in command
    return func(*args, **kwargs)
           ^^^^^^^^^^^^^^^^^^^^^
  File "/home/airflow/.local/lib/python3.12/site-packages/airflow/utils/cli.py", line 116, in wrapper
    return f(*args, **kwargs)
           ^^^^^^^^^^^^^^^^^^
  File "/home/airflow/.local/lib/python3.12/site-packages/airflow/cli/commands/task_command.py", line 483, in task_run
    task_return_code = _run_task_by_selected_method(args, _dag, ti)
                       ^^^^^^^^^^^^^^^^^^^^^^^^^^^^^^^^^^^^^^^^^^^^
  File "/home/airflow/.local/lib/python3.12/site-packages/airflow/cli/commands/task_command.py", line 256, in _run_task_by_selected_method
    return _run_raw_task(args, ti)
           ^^^^^^^^^^^^^^^^^^^^^^^
  File "/home/airflow/.local/lib/python3.12/site-packages/airflow/cli/commands/task_command.py", line 341, in _run_raw_task
    return ti._run_raw_task(
           ^^^^^^^^^^^^^^^^^
  File "/home/airflow/.local/lib/python3.12/site-packages/airflow/utils/session.py", line 97, in wrapper
    return func(*args, session=session, **kwargs)
           ^^^^^^^^^^^^^^^^^^^^^^^^^^^^^^^^^^^^^^
  File "/home/airflow/.local/lib/python3.12/site-packages/airflow/models/taskinstance.py", line 3006, in _run_raw_task
    return _run_raw_task(
           ^^^^^^^^^^^^^^
  File "/home/airflow/.local/lib/python3.12/site-packages/airflow/models/taskinstance.py", line 274, in _run_raw_task
    TaskInstance._execute_task_with_callbacks(
  File "/home/airflow/.local/lib/python3.12/site-packages/airflow/models/taskinstance.py", line 3161, in _execute_task_with_callbacks
    result = self._execute_task(context, task_orig)
             ^^^^^^^^^^^^^^^^^^^^^^^^^^^^^^^^^^^^^^
  File "/home/airflow/.local/lib/python3.12/site-packages/airflow/models/taskinstance.py", line 3185, in _execute_task
    return _execute_task(self, context, task_orig)
           ^^^^^^^^^^^^^^^^^^^^^^^^^^^^^^^^^^^^^^^
  File "/home/airflow/.local/lib/python3.12/site-packages/airflow/models/taskinstance.py", line 768, in _execute_task
    result = _execute_callable(context=context, **execute_callable_kwargs)
             ^^^^^^^^^^^^^^^^^^^^^^^^^^^^^^^^^^^^^^^^^^^^^^^^^^^^^^^^^^^^^
  File "/home/airflow/.local/lib/python3.12/site-packages/airflow/models/taskinstance.py", line 734, in _execute_callable
    return ExecutionCallableRunner(
           ^^^^^^^^^^^^^^^^^^^^^^^^
  File "/home/airflow/.local/lib/python3.12/site-packages/airflow/utils/operator_helpers.py", line 252, in run
    return self.func(*args, **kwargs)
           ^^^^^^^^^^^^^^^^^^^^^^^^^^
  File "/home/airflow/.local/lib/python3.12/site-packages/airflow/models/baseoperator.py", line 424, in wrapper
    return func(self, *args, **kwargs)
           ^^^^^^^^^^^^^^^^^^^^^^^^^^^
  File "/home/airflow/.local/lib/python3.12/site-packages/airflow/operators/bash.py", line 276, in execute
    raise AirflowException(
airflow.exceptions.AirflowException: Bash command failed. The command returned a non-zero exit code 1.
[2025-07-14T18:24:52.893+0000] {local_task_job_runner.py:266} INFO - Task exited with return code 1
[2025-07-14T18:24:52.967+0000] {taskinstance.py:3901} INFO - 0 downstream tasks scheduled from follow-on schedule check
[2025-07-14T18:24:52.978+0000] {local_task_job_runner.py:245} INFO - ::endgroup::
