[2025-07-14T15:42:02.647+0000] {local_task_job_runner.py:123} INFO - ::group::Pre task execution logs
[2025-07-14T15:42:02.687+0000] {taskinstance.py:2614} INFO - Dependencies all met for dep_context=non-requeueable deps ti=<TaskInstance: turnstile_ml_pipeline.train_model scheduled__2025-07-13T00:00:00+00:00 [queued]>
[2025-07-14T15:42:02.710+0000] {taskinstance.py:2614} INFO - Dependencies all met for dep_context=requeueable deps ti=<TaskInstance: turnstile_ml_pipeline.train_model scheduled__2025-07-13T00:00:00+00:00 [queued]>
[2025-07-14T15:42:02.712+0000] {taskinstance.py:2867} INFO - Starting attempt 5 of 5
[2025-07-14T15:42:02.741+0000] {taskinstance.py:2890} INFO - Executing <Task(BashOperator): train_model> on 2025-07-13 00:00:00+00:00
[2025-07-14T15:42:02.762+0000] {logging_mixin.py:190} WARNING - /home/***/.local/lib/python3.12/site-packages/***/task/task_runner/standard_task_runner.py:70 DeprecationWarning: This process (pid=1547) is multi-threaded, use of fork() may lead to deadlocks in the child.
[2025-07-14T15:42:02.764+0000] {standard_task_runner.py:72} INFO - Started process 1555 to run task
[2025-07-14T15:42:02.762+0000] {standard_task_runner.py:104} INFO - Running: ['***', 'tasks', 'run', 'turnstile_ml_pipeline', 'train_model', 'scheduled__2025-07-13T00:00:00+00:00', '--job-id', '24', '--raw', '--subdir', 'DAGS_FOLDER/pipeline_dag.py', '--cfg-path', '/tmp/tmpi9sa1cro']
[2025-07-14T15:42:02.780+0000] {standard_task_runner.py:105} INFO - Job 24: Subtask train_model
[2025-07-14T15:42:02.817+0000] {logging_mixin.py:190} WARNING - /home/***/.local/lib/python3.12/site-packages/***/settings.py:209 DeprecationWarning: The sql_alchemy_conn option in [core] has been moved to the sql_alchemy_conn option in [database] - the old setting has been used, but please update your config.
[2025-07-14T15:42:02.914+0000] {task_command.py:467} INFO - Running <TaskInstance: turnstile_ml_pipeline.train_model scheduled__2025-07-13T00:00:00+00:00 [running]> on host d84888688479
[2025-07-14T15:42:02.917+0000] {logging_mixin.py:190} WARNING - /home/***/.local/lib/python3.12/site-packages/***/settings.py:470 DeprecationWarning: The sql_alchemy_conn option in [core] has been moved to the sql_alchemy_conn option in [database] - the old setting has been used, but please update your config.
[2025-07-14T15:42:03.099+0000] {taskinstance.py:3134} INFO - Exporting env vars: AIRFLOW_CTX_DAG_OWNER='***' AIRFLOW_CTX_DAG_ID='turnstile_ml_pipeline' AIRFLOW_CTX_TASK_ID='train_model' AIRFLOW_CTX_EXECUTION_DATE='2025-07-13T00:00:00+00:00' AIRFLOW_CTX_TRY_NUMBER='5' AIRFLOW_CTX_DAG_RUN_ID='scheduled__2025-07-13T00:00:00+00:00'
[2025-07-14T15:42:03.101+0000] {taskinstance.py:732} INFO - ::endgroup::
[2025-07-14T15:42:03.133+0000] {subprocess.py:78} INFO - Tmp dir root location: /tmp
[2025-07-14T15:42:03.135+0000] {subprocess.py:88} INFO - Running command: ['/usr/bin/bash', '-c', '\n            python /opt/***/pipeline/train_register.py                             --user ***                 --password ***                 --host postgres                 --port 5432                 --db_name ny_sub_turnstiles                 --features_table turnstile_features         ']
[2025-07-14T15:42:03.157+0000] {subprocess.py:99} INFO - Output:
[2025-07-14T15:42:10.832+0000] {subprocess.py:106} INFO - 2025/07/14 15:42:10 WARNING mlflow.utils.git_utils: Failed to import Git (the Git executable is probably not on your PATH), so Git SHA is not available. Error: Failed to initialize: Bad git executable.
[2025-07-14T15:42:10.833+0000] {subprocess.py:106} INFO - The git executable must be specified in one of the following ways:
[2025-07-14T15:42:10.834+0000] {subprocess.py:106} INFO -     - be included in your $PATH
[2025-07-14T15:42:10.834+0000] {subprocess.py:106} INFO -     - be set via $GIT_PYTHON_GIT_EXECUTABLE
[2025-07-14T15:42:10.835+0000] {subprocess.py:106} INFO -     - explicitly set via git.refresh(<full-path-to-git-executable>)
[2025-07-14T15:42:10.836+0000] {subprocess.py:106} INFO - 
[2025-07-14T15:42:10.836+0000] {subprocess.py:106} INFO - All git commands will error until this is rectified.
[2025-07-14T15:42:10.837+0000] {subprocess.py:106} INFO - 
[2025-07-14T15:42:10.838+0000] {subprocess.py:106} INFO - This initial message can be silenced or aggravated in the future by setting the
[2025-07-14T15:42:10.838+0000] {subprocess.py:106} INFO - $GIT_PYTHON_REFRESH environment variable. Use one of the following values:
[2025-07-14T15:42:10.839+0000] {subprocess.py:106} INFO -     - quiet|q|silence|s|silent|none|n|0: for no message or exception
[2025-07-14T15:42:10.840+0000] {subprocess.py:106} INFO -     - warn|w|warning|log|l|1: for a warning message (logging level CRITICAL, displayed by default)
[2025-07-14T15:42:10.841+0000] {subprocess.py:106} INFO -     - error|e|exception|raise|r|2: for a raised exception
[2025-07-14T15:42:10.842+0000] {subprocess.py:106} INFO - 
[2025-07-14T15:42:10.844+0000] {subprocess.py:106} INFO - Example:
[2025-07-14T15:42:10.845+0000] {subprocess.py:106} INFO -     export GIT_PYTHON_REFRESH=quiet
[2025-07-14T15:42:10.845+0000] {subprocess.py:106} INFO - 
[2025-07-14T15:42:13.333+0000] {subprocess.py:106} INFO - üèÉ View run nebulous-worm-563 at: http://mlflow:5000/#/experiments/2/runs/c1d0e8e6bbf847348710c0edc078e727
[2025-07-14T15:42:13.335+0000] {subprocess.py:106} INFO - üß™ View experiment at: http://mlflow:5000/#/experiments/2
[2025-07-14T15:42:13.336+0000] {subprocess.py:106} INFO - Traceback (most recent call last):
[2025-07-14T15:42:13.337+0000] {subprocess.py:106} INFO -   File "/opt/***/pipeline/train_register.py", line 106, in <module>
[2025-07-14T15:42:13.338+0000] {subprocess.py:106} INFO -     train(df)
[2025-07-14T15:42:13.339+0000] {subprocess.py:106} INFO -   File "/opt/***/pipeline/train_register.py", line 83, in train
[2025-07-14T15:42:13.341+0000] {subprocess.py:106} INFO -     mlflow.xgboost.save_model(model, path=model_output_dir)
[2025-07-14T15:42:13.343+0000] {subprocess.py:106} INFO -   File "/home/***/.local/lib/python3.12/site-packages/mlflow/xgboost/__init__.py", line 147, in save_model
[2025-07-14T15:42:13.344+0000] {subprocess.py:106} INFO -     _validate_and_prepare_target_save_path(path)
[2025-07-14T15:42:13.345+0000] {subprocess.py:106} INFO -   File "/home/***/.local/lib/python3.12/site-packages/mlflow/utils/model_utils.py", line 271, in _validate_and_prepare_target_save_path
[2025-07-14T15:42:13.346+0000] {subprocess.py:106} INFO -     raise MlflowException(
[2025-07-14T15:42:13.347+0000] {subprocess.py:106} INFO - mlflow.exceptions.MlflowException: Path '/opt/***/shared' already exists and is not empty
[2025-07-14T15:42:14.036+0000] {subprocess.py:110} INFO - Command exited with return code 1
[2025-07-14T15:42:14.053+0000] {taskinstance.py:3313} ERROR - Task failed with exception
Traceback (most recent call last):
  File "/home/airflow/.local/lib/python3.12/site-packages/airflow/models/taskinstance.py", line 768, in _execute_task
    result = _execute_callable(context=context, **execute_callable_kwargs)
             ^^^^^^^^^^^^^^^^^^^^^^^^^^^^^^^^^^^^^^^^^^^^^^^^^^^^^^^^^^^^^
  File "/home/airflow/.local/lib/python3.12/site-packages/airflow/models/taskinstance.py", line 734, in _execute_callable
    return ExecutionCallableRunner(
           ^^^^^^^^^^^^^^^^^^^^^^^^
  File "/home/airflow/.local/lib/python3.12/site-packages/airflow/utils/operator_helpers.py", line 252, in run
    return self.func(*args, **kwargs)
           ^^^^^^^^^^^^^^^^^^^^^^^^^^
  File "/home/airflow/.local/lib/python3.12/site-packages/airflow/models/baseoperator.py", line 424, in wrapper
    return func(self, *args, **kwargs)
           ^^^^^^^^^^^^^^^^^^^^^^^^^^^
  File "/home/airflow/.local/lib/python3.12/site-packages/airflow/operators/bash.py", line 276, in execute
    raise AirflowException(
airflow.exceptions.AirflowException: Bash command failed. The command returned a non-zero exit code 1.
[2025-07-14T15:42:14.060+0000] {taskinstance.py:1226} INFO - Marking task as FAILED. dag_id=turnstile_ml_pipeline, task_id=train_model, run_id=scheduled__2025-07-13T00:00:00+00:00, execution_date=20250713T000000, start_date=20250714T154202, end_date=20250714T154214
[2025-07-14T15:42:14.107+0000] {taskinstance.py:341} INFO - ::group::Post task execution logs
[2025-07-14T15:42:14.109+0000] {standard_task_runner.py:124} ERROR - Failed to execute job 24 for task train_model (Bash command failed. The command returned a non-zero exit code 1.; 1555)
Traceback (most recent call last):
  File "/home/airflow/.local/lib/python3.12/site-packages/airflow/task/task_runner/standard_task_runner.py", line 117, in _start_by_fork
    ret = args.func(args, dag=self.dag)
          ^^^^^^^^^^^^^^^^^^^^^^^^^^^^^
  File "/home/airflow/.local/lib/python3.12/site-packages/airflow/cli/cli_config.py", line 49, in command
    return func(*args, **kwargs)
           ^^^^^^^^^^^^^^^^^^^^^
  File "/home/airflow/.local/lib/python3.12/site-packages/airflow/utils/cli.py", line 116, in wrapper
    return f(*args, **kwargs)
           ^^^^^^^^^^^^^^^^^^
  File "/home/airflow/.local/lib/python3.12/site-packages/airflow/cli/commands/task_command.py", line 483, in task_run
    task_return_code = _run_task_by_selected_method(args, _dag, ti)
                       ^^^^^^^^^^^^^^^^^^^^^^^^^^^^^^^^^^^^^^^^^^^^
  File "/home/airflow/.local/lib/python3.12/site-packages/airflow/cli/commands/task_command.py", line 256, in _run_task_by_selected_method
    return _run_raw_task(args, ti)
           ^^^^^^^^^^^^^^^^^^^^^^^
  File "/home/airflow/.local/lib/python3.12/site-packages/airflow/cli/commands/task_command.py", line 341, in _run_raw_task
    return ti._run_raw_task(
           ^^^^^^^^^^^^^^^^^
  File "/home/airflow/.local/lib/python3.12/site-packages/airflow/utils/session.py", line 97, in wrapper
    return func(*args, session=session, **kwargs)
           ^^^^^^^^^^^^^^^^^^^^^^^^^^^^^^^^^^^^^^
  File "/home/airflow/.local/lib/python3.12/site-packages/airflow/models/taskinstance.py", line 3006, in _run_raw_task
    return _run_raw_task(
           ^^^^^^^^^^^^^^
  File "/home/airflow/.local/lib/python3.12/site-packages/airflow/models/taskinstance.py", line 274, in _run_raw_task
    TaskInstance._execute_task_with_callbacks(
  File "/home/airflow/.local/lib/python3.12/site-packages/airflow/models/taskinstance.py", line 3161, in _execute_task_with_callbacks
    result = self._execute_task(context, task_orig)
             ^^^^^^^^^^^^^^^^^^^^^^^^^^^^^^^^^^^^^^
  File "/home/airflow/.local/lib/python3.12/site-packages/airflow/models/taskinstance.py", line 3185, in _execute_task
    return _execute_task(self, context, task_orig)
           ^^^^^^^^^^^^^^^^^^^^^^^^^^^^^^^^^^^^^^^
  File "/home/airflow/.local/lib/python3.12/site-packages/airflow/models/taskinstance.py", line 768, in _execute_task
    result = _execute_callable(context=context, **execute_callable_kwargs)
             ^^^^^^^^^^^^^^^^^^^^^^^^^^^^^^^^^^^^^^^^^^^^^^^^^^^^^^^^^^^^^
  File "/home/airflow/.local/lib/python3.12/site-packages/airflow/models/taskinstance.py", line 734, in _execute_callable
    return ExecutionCallableRunner(
           ^^^^^^^^^^^^^^^^^^^^^^^^
  File "/home/airflow/.local/lib/python3.12/site-packages/airflow/utils/operator_helpers.py", line 252, in run
    return self.func(*args, **kwargs)
           ^^^^^^^^^^^^^^^^^^^^^^^^^^
  File "/home/airflow/.local/lib/python3.12/site-packages/airflow/models/baseoperator.py", line 424, in wrapper
    return func(self, *args, **kwargs)
           ^^^^^^^^^^^^^^^^^^^^^^^^^^^
  File "/home/airflow/.local/lib/python3.12/site-packages/airflow/operators/bash.py", line 276, in execute
    raise AirflowException(
airflow.exceptions.AirflowException: Bash command failed. The command returned a non-zero exit code 1.
[2025-07-14T15:42:14.131+0000] {local_task_job_runner.py:266} INFO - Task exited with return code 1
[2025-07-14T15:42:14.172+0000] {taskinstance.py:3901} INFO - 0 downstream tasks scheduled from follow-on schedule check
[2025-07-14T15:42:14.180+0000] {local_task_job_runner.py:245} INFO - ::endgroup::
