[2025-07-14T15:23:22.054+0000] {local_task_job_runner.py:123} INFO - ::group::Pre task execution logs
[2025-07-14T15:23:22.100+0000] {taskinstance.py:2614} INFO - Dependencies all met for dep_context=non-requeueable deps ti=<TaskInstance: turnstile_ml_pipeline.train_model scheduled__2025-07-13T00:00:00+00:00 [queued]>
[2025-07-14T15:23:22.118+0000] {taskinstance.py:2614} INFO - Dependencies all met for dep_context=requeueable deps ti=<TaskInstance: turnstile_ml_pipeline.train_model scheduled__2025-07-13T00:00:00+00:00 [queued]>
[2025-07-14T15:23:22.119+0000] {taskinstance.py:2867} INFO - Starting attempt 3 of 3
[2025-07-14T15:23:22.144+0000] {taskinstance.py:2890} INFO - Executing <Task(BashOperator): train_model> on 2025-07-13 00:00:00+00:00
[2025-07-14T15:23:22.173+0000] {logging_mixin.py:190} WARNING - /home/***/.local/lib/python3.12/site-packages/***/task/task_runner/standard_task_runner.py:70 DeprecationWarning: This process (pid=1415) is multi-threaded, use of fork() may lead to deadlocks in the child.
[2025-07-14T15:23:22.182+0000] {standard_task_runner.py:72} INFO - Started process 1421 to run task
[2025-07-14T15:23:22.176+0000] {standard_task_runner.py:104} INFO - Running: ['***', 'tasks', 'run', 'turnstile_ml_pipeline', 'train_model', 'scheduled__2025-07-13T00:00:00+00:00', '--job-id', '22', '--raw', '--subdir', 'DAGS_FOLDER/pipeline_dag.py', '--cfg-path', '/tmp/tmpzk4euc7_']
[2025-07-14T15:23:22.191+0000] {standard_task_runner.py:105} INFO - Job 22: Subtask train_model
[2025-07-14T15:23:22.256+0000] {logging_mixin.py:190} WARNING - /home/***/.local/lib/python3.12/site-packages/***/settings.py:209 DeprecationWarning: The sql_alchemy_conn option in [core] has been moved to the sql_alchemy_conn option in [database] - the old setting has been used, but please update your config.
[2025-07-14T15:23:22.405+0000] {task_command.py:467} INFO - Running <TaskInstance: turnstile_ml_pipeline.train_model scheduled__2025-07-13T00:00:00+00:00 [running]> on host d84888688479
[2025-07-14T15:23:22.411+0000] {logging_mixin.py:190} WARNING - /home/***/.local/lib/python3.12/site-packages/***/settings.py:470 DeprecationWarning: The sql_alchemy_conn option in [core] has been moved to the sql_alchemy_conn option in [database] - the old setting has been used, but please update your config.
[2025-07-14T15:23:22.621+0000] {taskinstance.py:3134} INFO - Exporting env vars: AIRFLOW_CTX_DAG_OWNER='***' AIRFLOW_CTX_DAG_ID='turnstile_ml_pipeline' AIRFLOW_CTX_TASK_ID='train_model' AIRFLOW_CTX_EXECUTION_DATE='2025-07-13T00:00:00+00:00' AIRFLOW_CTX_TRY_NUMBER='3' AIRFLOW_CTX_DAG_RUN_ID='scheduled__2025-07-13T00:00:00+00:00'
[2025-07-14T15:23:22.627+0000] {taskinstance.py:732} INFO - ::endgroup::
[2025-07-14T15:23:22.709+0000] {subprocess.py:78} INFO - Tmp dir root location: /tmp
[2025-07-14T15:23:22.711+0000] {subprocess.py:88} INFO - Running command: ['/usr/bin/bash', '-c', '\n            python /opt/***/pipeline/train_register.py                             --user ***                 --password ***                 --host postgres                 --port 5432                 --db_name ny_sub_turnstiles                 --features_table turnstile_features         ']
[2025-07-14T15:23:22.747+0000] {subprocess.py:99} INFO - Output:
[2025-07-14T15:23:32.470+0000] {subprocess.py:106} INFO - 2025/07/14 15:23:32 WARNING mlflow.utils.git_utils: Failed to import Git (the Git executable is probably not on your PATH), so Git SHA is not available. Error: Failed to initialize: Bad git executable.
[2025-07-14T15:23:32.473+0000] {subprocess.py:106} INFO - The git executable must be specified in one of the following ways:
[2025-07-14T15:23:32.475+0000] {subprocess.py:106} INFO -     - be included in your $PATH
[2025-07-14T15:23:32.477+0000] {subprocess.py:106} INFO -     - be set via $GIT_PYTHON_GIT_EXECUTABLE
[2025-07-14T15:23:32.478+0000] {subprocess.py:106} INFO -     - explicitly set via git.refresh(<full-path-to-git-executable>)
[2025-07-14T15:23:32.480+0000] {subprocess.py:106} INFO - 
[2025-07-14T15:23:32.481+0000] {subprocess.py:106} INFO - All git commands will error until this is rectified.
[2025-07-14T15:23:32.482+0000] {subprocess.py:106} INFO - 
[2025-07-14T15:23:32.483+0000] {subprocess.py:106} INFO - This initial message can be silenced or aggravated in the future by setting the
[2025-07-14T15:23:32.493+0000] {subprocess.py:106} INFO - $GIT_PYTHON_REFRESH environment variable. Use one of the following values:
[2025-07-14T15:23:32.495+0000] {subprocess.py:106} INFO -     - quiet|q|silence|s|silent|none|n|0: for no message or exception
[2025-07-14T15:23:32.497+0000] {subprocess.py:106} INFO -     - warn|w|warning|log|l|1: for a warning message (logging level CRITICAL, displayed by default)
[2025-07-14T15:23:32.499+0000] {subprocess.py:106} INFO -     - error|e|exception|raise|r|2: for a raised exception
[2025-07-14T15:23:32.500+0000] {subprocess.py:106} INFO - 
[2025-07-14T15:23:32.501+0000] {subprocess.py:106} INFO - Example:
[2025-07-14T15:23:32.503+0000] {subprocess.py:106} INFO -     export GIT_PYTHON_REFRESH=quiet
[2025-07-14T15:23:32.511+0000] {subprocess.py:106} INFO - 
[2025-07-14T15:23:50.838+0000] {subprocess.py:106} INFO - üèÉ View run zealous-kit-375 at: http://mlflow:5000/#/experiments/2/runs/b1429aad196f494aad3f88df5ff2918a
[2025-07-14T15:23:50.840+0000] {subprocess.py:106} INFO - üß™ View experiment at: http://mlflow:5000/#/experiments/2
[2025-07-14T15:23:50.841+0000] {subprocess.py:106} INFO - Traceback (most recent call last):
[2025-07-14T15:23:50.843+0000] {subprocess.py:106} INFO -   File "/opt/***/pipeline/train_register.py", line 106, in <module>
[2025-07-14T15:23:50.846+0000] {subprocess.py:106} INFO -     train(df)
[2025-07-14T15:23:50.847+0000] {subprocess.py:106} INFO -   File "/opt/***/pipeline/train_register.py", line 84, in train
[2025-07-14T15:23:50.850+0000] {subprocess.py:106} INFO -     mlflow.log_artifacts(model_output_dir, artifact_path="model")
[2025-07-14T15:23:50.852+0000] {subprocess.py:106} INFO -   File "/home/***/.local/lib/python3.12/site-packages/mlflow/tracking/fluent.py", line 1444, in log_artifacts
[2025-07-14T15:23:50.855+0000] {subprocess.py:106} INFO -     MlflowClient().log_artifacts(run_id, local_dir, artifact_path)
[2025-07-14T15:23:50.857+0000] {subprocess.py:106} INFO -   File "/home/***/.local/lib/python3.12/site-packages/mlflow/tracking/client.py", line 2497, in log_artifacts
[2025-07-14T15:23:50.860+0000] {subprocess.py:106} INFO -     self._tracking_client.log_artifacts(run_id, local_dir, artifact_path)
[2025-07-14T15:23:50.861+0000] {subprocess.py:106} INFO -   File "/home/***/.local/lib/python3.12/site-packages/mlflow/tracking/_tracking_service/client.py", line 663, in log_artifacts
[2025-07-14T15:23:50.862+0000] {subprocess.py:106} INFO -     self._get_artifact_repo(run_id).log_artifacts(local_dir, artifact_path)
[2025-07-14T15:23:50.864+0000] {subprocess.py:106} INFO -   File "/home/***/.local/lib/python3.12/site-packages/mlflow/store/artifact/local_artifact_repo.py", line 67, in log_artifacts
[2025-07-14T15:23:50.865+0000] {subprocess.py:106} INFO -     shutil.copytree(src=local_dir, dst=artifact_dir, dirs_exist_ok=True)
[2025-07-14T15:23:50.866+0000] {subprocess.py:106} INFO -   File "/usr/local/lib/python3.12/shutil.py", line 600, in copytree
[2025-07-14T15:23:50.879+0000] {subprocess.py:106} INFO -     return _copytree(entries=entries, src=src, dst=dst, symlinks=symlinks,
[2025-07-14T15:23:50.881+0000] {subprocess.py:106} INFO -            ^^^^^^^^^^^^^^^^^^^^^^^^^^^^^^^^^^^^^^^^^^^^^^^^^^^^^^^^^^^^^^^
[2025-07-14T15:23:50.881+0000] {subprocess.py:106} INFO -   File "/usr/local/lib/python3.12/shutil.py", line 554, in _copytree
[2025-07-14T15:23:50.882+0000] {subprocess.py:106} INFO -     raise Error(errors)
[2025-07-14T15:23:50.883+0000] {subprocess.py:106} INFO - shutil.Error: [('mlflow/xgb_model_local/MLmodel', '/mlflow/2/b1429aad196f494aad3f88df5ff2918a/artifacts/model/MLmodel', '[Errno 1] Operation not permitted'), ('mlflow/xgb_model_local/conda.yaml', '/mlflow/2/b1429aad196f494aad3f88df5ff2918a/artifacts/model/conda.yaml', '[Errno 1] Operation not permitted'), ('mlflow/xgb_model_local/model.xgb', '/mlflow/2/b1429aad196f494aad3f88df5ff2918a/artifacts/model/model.xgb', '[Errno 1] Operation not permitted'), ('mlflow/xgb_model_local/python_env.yaml', '/mlflow/2/b1429aad196f494aad3f88df5ff2918a/artifacts/model/python_env.yaml', '[Errno 1] Operation not permitted'), ('mlflow/xgb_model_local/requirements.txt', '/mlflow/2/b1429aad196f494aad3f88df5ff2918a/artifacts/model/requirements.txt', '[Errno 1] Operation not permitted'), ('mlflow/xgb_model_local', '/mlflow/2/b1429aad196f494aad3f88df5ff2918a/artifacts/model', '[Errno 1] Operation not permitted')]
[2025-07-14T15:23:51.658+0000] {subprocess.py:110} INFO - Command exited with return code 1
[2025-07-14T15:23:51.693+0000] {taskinstance.py:3313} ERROR - Task failed with exception
Traceback (most recent call last):
  File "/home/airflow/.local/lib/python3.12/site-packages/airflow/models/taskinstance.py", line 768, in _execute_task
    result = _execute_callable(context=context, **execute_callable_kwargs)
             ^^^^^^^^^^^^^^^^^^^^^^^^^^^^^^^^^^^^^^^^^^^^^^^^^^^^^^^^^^^^^
  File "/home/airflow/.local/lib/python3.12/site-packages/airflow/models/taskinstance.py", line 734, in _execute_callable
    return ExecutionCallableRunner(
           ^^^^^^^^^^^^^^^^^^^^^^^^
  File "/home/airflow/.local/lib/python3.12/site-packages/airflow/utils/operator_helpers.py", line 252, in run
    return self.func(*args, **kwargs)
           ^^^^^^^^^^^^^^^^^^^^^^^^^^
  File "/home/airflow/.local/lib/python3.12/site-packages/airflow/models/baseoperator.py", line 424, in wrapper
    return func(self, *args, **kwargs)
           ^^^^^^^^^^^^^^^^^^^^^^^^^^^
  File "/home/airflow/.local/lib/python3.12/site-packages/airflow/operators/bash.py", line 276, in execute
    raise AirflowException(
airflow.exceptions.AirflowException: Bash command failed. The command returned a non-zero exit code 1.
[2025-07-14T15:23:51.710+0000] {taskinstance.py:1226} INFO - Marking task as FAILED. dag_id=turnstile_ml_pipeline, task_id=train_model, run_id=scheduled__2025-07-13T00:00:00+00:00, execution_date=20250713T000000, start_date=20250714T152322, end_date=20250714T152351
[2025-07-14T15:23:51.810+0000] {taskinstance.py:341} INFO - ::group::Post task execution logs
[2025-07-14T15:23:51.812+0000] {standard_task_runner.py:124} ERROR - Failed to execute job 22 for task train_model (Bash command failed. The command returned a non-zero exit code 1.; 1421)
Traceback (most recent call last):
  File "/home/airflow/.local/lib/python3.12/site-packages/airflow/task/task_runner/standard_task_runner.py", line 117, in _start_by_fork
    ret = args.func(args, dag=self.dag)
          ^^^^^^^^^^^^^^^^^^^^^^^^^^^^^
  File "/home/airflow/.local/lib/python3.12/site-packages/airflow/cli/cli_config.py", line 49, in command
    return func(*args, **kwargs)
           ^^^^^^^^^^^^^^^^^^^^^
  File "/home/airflow/.local/lib/python3.12/site-packages/airflow/utils/cli.py", line 116, in wrapper
    return f(*args, **kwargs)
           ^^^^^^^^^^^^^^^^^^
  File "/home/airflow/.local/lib/python3.12/site-packages/airflow/cli/commands/task_command.py", line 483, in task_run
    task_return_code = _run_task_by_selected_method(args, _dag, ti)
                       ^^^^^^^^^^^^^^^^^^^^^^^^^^^^^^^^^^^^^^^^^^^^
  File "/home/airflow/.local/lib/python3.12/site-packages/airflow/cli/commands/task_command.py", line 256, in _run_task_by_selected_method
    return _run_raw_task(args, ti)
           ^^^^^^^^^^^^^^^^^^^^^^^
  File "/home/airflow/.local/lib/python3.12/site-packages/airflow/cli/commands/task_command.py", line 341, in _run_raw_task
    return ti._run_raw_task(
           ^^^^^^^^^^^^^^^^^
  File "/home/airflow/.local/lib/python3.12/site-packages/airflow/utils/session.py", line 97, in wrapper
    return func(*args, session=session, **kwargs)
           ^^^^^^^^^^^^^^^^^^^^^^^^^^^^^^^^^^^^^^
  File "/home/airflow/.local/lib/python3.12/site-packages/airflow/models/taskinstance.py", line 3006, in _run_raw_task
    return _run_raw_task(
           ^^^^^^^^^^^^^^
  File "/home/airflow/.local/lib/python3.12/site-packages/airflow/models/taskinstance.py", line 274, in _run_raw_task
    TaskInstance._execute_task_with_callbacks(
  File "/home/airflow/.local/lib/python3.12/site-packages/airflow/models/taskinstance.py", line 3161, in _execute_task_with_callbacks
    result = self._execute_task(context, task_orig)
             ^^^^^^^^^^^^^^^^^^^^^^^^^^^^^^^^^^^^^^
  File "/home/airflow/.local/lib/python3.12/site-packages/airflow/models/taskinstance.py", line 3185, in _execute_task
    return _execute_task(self, context, task_orig)
           ^^^^^^^^^^^^^^^^^^^^^^^^^^^^^^^^^^^^^^^
  File "/home/airflow/.local/lib/python3.12/site-packages/airflow/models/taskinstance.py", line 768, in _execute_task
    result = _execute_callable(context=context, **execute_callable_kwargs)
             ^^^^^^^^^^^^^^^^^^^^^^^^^^^^^^^^^^^^^^^^^^^^^^^^^^^^^^^^^^^^^
  File "/home/airflow/.local/lib/python3.12/site-packages/airflow/models/taskinstance.py", line 734, in _execute_callable
    return ExecutionCallableRunner(
           ^^^^^^^^^^^^^^^^^^^^^^^^
  File "/home/airflow/.local/lib/python3.12/site-packages/airflow/utils/operator_helpers.py", line 252, in run
    return self.func(*args, **kwargs)
           ^^^^^^^^^^^^^^^^^^^^^^^^^^
  File "/home/airflow/.local/lib/python3.12/site-packages/airflow/models/baseoperator.py", line 424, in wrapper
    return func(self, *args, **kwargs)
           ^^^^^^^^^^^^^^^^^^^^^^^^^^^
  File "/home/airflow/.local/lib/python3.12/site-packages/airflow/operators/bash.py", line 276, in execute
    raise AirflowException(
airflow.exceptions.AirflowException: Bash command failed. The command returned a non-zero exit code 1.
[2025-07-14T15:23:51.860+0000] {local_task_job_runner.py:266} INFO - Task exited with return code 1
[2025-07-14T15:23:51.907+0000] {taskinstance.py:3901} INFO - 0 downstream tasks scheduled from follow-on schedule check
[2025-07-14T15:23:51.920+0000] {local_task_job_runner.py:245} INFO - ::endgroup::
