[2025-07-13T19:17:37.006+0000] {local_task_job_runner.py:123} INFO - ::group::Pre task execution logs
[2025-07-13T19:17:37.192+0000] {taskinstance.py:2614} INFO - Dependencies all met for dep_context=non-requeueable deps ti=<TaskInstance: turnstile_ml_pipeline.train_model manual__2025-07-13T17:16:28+00:00 [queued]>
[2025-07-13T19:17:37.227+0000] {taskinstance.py:2614} INFO - Dependencies all met for dep_context=requeueable deps ti=<TaskInstance: turnstile_ml_pipeline.train_model manual__2025-07-13T17:16:28+00:00 [queued]>
[2025-07-13T19:17:37.228+0000] {taskinstance.py:2867} INFO - Starting attempt 3 of 3
[2025-07-13T19:17:37.266+0000] {taskinstance.py:2890} INFO - Executing <Task(BashOperator): train_model> on 2025-07-13 17:16:28+00:00
[2025-07-13T19:17:37.284+0000] {logging_mixin.py:190} WARNING - /home/***/.local/lib/python3.12/site-packages/***/task/task_runner/standard_task_runner.py:70 DeprecationWarning: This process (pid=454) is multi-threaded, use of fork() may lead to deadlocks in the child.
[2025-07-13T19:17:37.287+0000] {standard_task_runner.py:72} INFO - Started process 460 to run task
[2025-07-13T19:17:37.285+0000] {standard_task_runner.py:104} INFO - Running: ['***', 'tasks', 'run', 'turnstile_ml_pipeline', 'train_model', 'manual__2025-07-13T17:16:28+00:00', '--job-id', '11', '--raw', '--subdir', 'DAGS_FOLDER/pipeline_dag.py', '--cfg-path', '/tmp/tmpshuag2zd']
[2025-07-13T19:17:37.290+0000] {standard_task_runner.py:105} INFO - Job 11: Subtask train_model
[2025-07-13T19:17:37.321+0000] {logging_mixin.py:190} WARNING - /home/***/.local/lib/python3.12/site-packages/***/settings.py:209 DeprecationWarning: The sql_alchemy_conn option in [core] has been moved to the sql_alchemy_conn option in [database] - the old setting has been used, but please update your config.
[2025-07-13T19:17:37.408+0000] {task_command.py:467} INFO - Running <TaskInstance: turnstile_ml_pipeline.train_model manual__2025-07-13T17:16:28+00:00 [running]> on host d84888688479
[2025-07-13T19:17:37.608+0000] {taskinstance.py:3134} INFO - Exporting env vars: AIRFLOW_CTX_DAG_OWNER='***' AIRFLOW_CTX_DAG_ID='turnstile_ml_pipeline' AIRFLOW_CTX_TASK_ID='train_model' AIRFLOW_CTX_EXECUTION_DATE='2025-07-13T17:16:28+00:00' AIRFLOW_CTX_TRY_NUMBER='3' AIRFLOW_CTX_DAG_RUN_ID='manual__2025-07-13T17:16:28+00:00'
[2025-07-13T19:17:37.610+0000] {taskinstance.py:732} INFO - ::endgroup::
[2025-07-13T19:17:37.671+0000] {subprocess.py:78} INFO - Tmp dir root location: /tmp
[2025-07-13T19:17:37.673+0000] {subprocess.py:88} INFO - Running command: ['/usr/bin/bash', '-c', '\n            python /opt/***/pipeline/train_register.py                             --user ***                 --password ***                 --host postgres                 --port 5432                 --db_name ny_sub_turnstiles                 --features_table turnstile_features         ']
[2025-07-13T19:17:37.705+0000] {subprocess.py:99} INFO - Output:
[2025-07-13T19:21:53.841+0000] {subprocess.py:106} INFO - Traceback (most recent call last):
[2025-07-13T19:21:53.844+0000] {subprocess.py:106} INFO -   File "/home/***/.local/lib/python3.12/site-packages/urllib3/connection.py", line 198, in _new_conn
[2025-07-13T19:21:53.846+0000] {subprocess.py:106} INFO -     sock = connection.create_connection(
[2025-07-13T19:21:53.846+0000] {subprocess.py:106} INFO -            ^^^^^^^^^^^^^^^^^^^^^^^^^^^^^
[2025-07-13T19:21:53.847+0000] {subprocess.py:106} INFO -   File "/home/***/.local/lib/python3.12/site-packages/urllib3/util/connection.py", line 85, in create_connection
[2025-07-13T19:21:53.848+0000] {subprocess.py:106} INFO -     raise err
[2025-07-13T19:21:53.849+0000] {subprocess.py:106} INFO -   File "/home/***/.local/lib/python3.12/site-packages/urllib3/util/connection.py", line 73, in create_connection
[2025-07-13T19:21:53.850+0000] {subprocess.py:106} INFO -     sock.connect(sa)
[2025-07-13T19:21:53.851+0000] {subprocess.py:106} INFO - ConnectionRefusedError: [Errno 111] Connection refused
[2025-07-13T19:21:53.851+0000] {subprocess.py:106} INFO - 
[2025-07-13T19:21:53.852+0000] {subprocess.py:106} INFO - The above exception was the direct cause of the following exception:
[2025-07-13T19:21:53.852+0000] {subprocess.py:106} INFO - 
[2025-07-13T19:21:53.853+0000] {subprocess.py:106} INFO - Traceback (most recent call last):
[2025-07-13T19:21:53.853+0000] {subprocess.py:106} INFO -   File "/home/***/.local/lib/python3.12/site-packages/urllib3/connectionpool.py", line 787, in urlopen
[2025-07-13T19:21:53.854+0000] {subprocess.py:106} INFO -     response = self._make_request(
[2025-07-13T19:21:53.855+0000] {subprocess.py:106} INFO -                ^^^^^^^^^^^^^^^^^^^
[2025-07-13T19:21:53.855+0000] {subprocess.py:106} INFO -   File "/home/***/.local/lib/python3.12/site-packages/urllib3/connectionpool.py", line 493, in _make_request
[2025-07-13T19:21:53.855+0000] {subprocess.py:106} INFO -     conn.request(
[2025-07-13T19:21:53.856+0000] {subprocess.py:106} INFO -   File "/home/***/.local/lib/python3.12/site-packages/urllib3/connection.py", line 445, in request
[2025-07-13T19:21:53.856+0000] {subprocess.py:106} INFO -     self.endheaders()
[2025-07-13T19:21:53.857+0000] {subprocess.py:106} INFO -   File "/usr/local/lib/python3.12/http/client.py", line 1333, in endheaders
[2025-07-13T19:21:53.857+0000] {subprocess.py:106} INFO -     self._send_output(message_body, encode_chunked=encode_chunked)
[2025-07-13T19:21:53.858+0000] {subprocess.py:106} INFO -   File "/usr/local/lib/python3.12/http/client.py", line 1093, in _send_output
[2025-07-13T19:21:53.859+0000] {subprocess.py:106} INFO -     self.send(msg)
[2025-07-13T19:21:53.860+0000] {subprocess.py:106} INFO -   File "/usr/local/lib/python3.12/http/client.py", line 1037, in send
[2025-07-13T19:21:53.861+0000] {subprocess.py:106} INFO -     self.connect()
[2025-07-13T19:21:53.862+0000] {subprocess.py:106} INFO -   File "/home/***/.local/lib/python3.12/site-packages/urllib3/connection.py", line 276, in connect
[2025-07-13T19:21:53.863+0000] {subprocess.py:106} INFO -     self.sock = self._new_conn()
[2025-07-13T19:21:53.864+0000] {subprocess.py:106} INFO -                 ^^^^^^^^^^^^^^^^
[2025-07-13T19:21:53.865+0000] {subprocess.py:106} INFO -   File "/home/***/.local/lib/python3.12/site-packages/urllib3/connection.py", line 213, in _new_conn
[2025-07-13T19:21:53.866+0000] {subprocess.py:106} INFO -     raise NewConnectionError(
[2025-07-13T19:21:53.866+0000] {subprocess.py:106} INFO - urllib3.exceptions.NewConnectionError: <urllib3.connection.HTTPConnection object at 0x7f360b635be0>: Failed to establish a new connection: [Errno 111] Connection refused
[2025-07-13T19:21:53.867+0000] {subprocess.py:106} INFO - 
[2025-07-13T19:21:53.867+0000] {subprocess.py:106} INFO - The above exception was the direct cause of the following exception:
[2025-07-13T19:21:53.868+0000] {subprocess.py:106} INFO - 
[2025-07-13T19:21:53.868+0000] {subprocess.py:106} INFO - Traceback (most recent call last):
[2025-07-13T19:21:53.869+0000] {subprocess.py:106} INFO -   File "/home/***/.local/lib/python3.12/site-packages/requests/adapters.py", line 667, in send
[2025-07-13T19:21:53.870+0000] {subprocess.py:106} INFO -     resp = conn.urlopen(
[2025-07-13T19:21:53.871+0000] {subprocess.py:106} INFO -            ^^^^^^^^^^^^^
[2025-07-13T19:21:53.872+0000] {subprocess.py:106} INFO -   File "/home/***/.local/lib/python3.12/site-packages/urllib3/connectionpool.py", line 871, in urlopen
[2025-07-13T19:21:53.872+0000] {subprocess.py:106} INFO -     return self.urlopen(
[2025-07-13T19:21:53.873+0000] {subprocess.py:106} INFO -            ^^^^^^^^^^^^^
[2025-07-13T19:21:53.874+0000] {subprocess.py:106} INFO -   File "/home/***/.local/lib/python3.12/site-packages/urllib3/connectionpool.py", line 871, in urlopen
[2025-07-13T19:21:53.874+0000] {subprocess.py:106} INFO -     return self.urlopen(
[2025-07-13T19:21:53.875+0000] {subprocess.py:106} INFO -            ^^^^^^^^^^^^^
[2025-07-13T19:21:53.876+0000] {subprocess.py:106} INFO -   File "/home/***/.local/lib/python3.12/site-packages/urllib3/connectionpool.py", line 871, in urlopen
[2025-07-13T19:21:53.877+0000] {subprocess.py:106} INFO -     return self.urlopen(
[2025-07-13T19:21:53.878+0000] {subprocess.py:106} INFO -            ^^^^^^^^^^^^^
[2025-07-13T19:21:53.878+0000] {subprocess.py:106} INFO -   [Previous line repeated 4 more times]
[2025-07-13T19:21:53.879+0000] {subprocess.py:106} INFO -   File "/home/***/.local/lib/python3.12/site-packages/urllib3/connectionpool.py", line 841, in urlopen
[2025-07-13T19:21:53.880+0000] {subprocess.py:106} INFO -     retries = retries.increment(
[2025-07-13T19:21:53.880+0000] {subprocess.py:106} INFO -               ^^^^^^^^^^^^^^^^^^
[2025-07-13T19:21:53.881+0000] {subprocess.py:106} INFO -   File "/home/***/.local/lib/python3.12/site-packages/urllib3/util/retry.py", line 519, in increment
[2025-07-13T19:21:53.882+0000] {subprocess.py:106} INFO -     raise MaxRetryError(_pool, url, reason) from reason  # type: ignore[arg-type]
[2025-07-13T19:21:53.886+0000] {subprocess.py:106} INFO -     ^^^^^^^^^^^^^^^^^^^^^^^^^^^^^^^^^^^^^^^^^^^^^^^^^^^
[2025-07-13T19:21:53.887+0000] {subprocess.py:106} INFO - urllib3.exceptions.MaxRetryError: HTTPConnectionPool(host='127.0.0.1', port=5000): Max retries exceeded with url: /api/2.0/mlflow/experiments/get-by-name?experiment_name=xgboost-hyperopt (Caused by NewConnectionError('<urllib3.connection.HTTPConnection object at 0x7f360b635be0>: Failed to establish a new connection: [Errno 111] Connection refused'))
[2025-07-13T19:21:53.887+0000] {subprocess.py:106} INFO - 
[2025-07-13T19:21:53.888+0000] {subprocess.py:106} INFO - During handling of the above exception, another exception occurred:
[2025-07-13T19:21:53.888+0000] {subprocess.py:106} INFO - 
[2025-07-13T19:21:53.889+0000] {subprocess.py:106} INFO - Traceback (most recent call last):
[2025-07-13T19:21:53.889+0000] {subprocess.py:106} INFO -   File "/home/***/.local/lib/python3.12/site-packages/mlflow/utils/rest_utils.py", line 229, in http_request
[2025-07-13T19:21:53.890+0000] {subprocess.py:106} INFO -     return _get_http_response_with_retries(
[2025-07-13T19:21:53.890+0000] {subprocess.py:106} INFO -            ^^^^^^^^^^^^^^^^^^^^^^^^^^^^^^^^
[2025-07-13T19:21:53.890+0000] {subprocess.py:106} INFO -   File "/home/***/.local/lib/python3.12/site-packages/mlflow/utils/request_utils.py", line 237, in _get_http_response_with_retries
[2025-07-13T19:21:53.891+0000] {subprocess.py:106} INFO -     return session.request(method, url, allow_redirects=allow_redirects, **kwargs)
[2025-07-13T19:21:53.892+0000] {subprocess.py:106} INFO -            ^^^^^^^^^^^^^^^^^^^^^^^^^^^^^^^^^^^^^^^^^^^^^^^^^^^^^^^^^^^^^^^^^^^^^^^
[2025-07-13T19:21:53.894+0000] {subprocess.py:106} INFO -   File "/home/***/.local/lib/python3.12/site-packages/requests/sessions.py", line 589, in request
[2025-07-13T19:21:53.895+0000] {subprocess.py:106} INFO -     resp = self.send(prep, **send_kwargs)
[2025-07-13T19:21:53.896+0000] {subprocess.py:106} INFO -            ^^^^^^^^^^^^^^^^^^^^^^^^^^^^^^
[2025-07-13T19:21:53.898+0000] {subprocess.py:106} INFO -   File "/home/***/.local/lib/python3.12/site-packages/requests/sessions.py", line 703, in send
[2025-07-13T19:21:53.899+0000] {subprocess.py:106} INFO -     r = adapter.send(request, **kwargs)
[2025-07-13T19:21:53.899+0000] {subprocess.py:106} INFO -         ^^^^^^^^^^^^^^^^^^^^^^^^^^^^^^^
[2025-07-13T19:21:53.900+0000] {subprocess.py:106} INFO -   File "/home/***/.local/lib/python3.12/site-packages/requests/adapters.py", line 700, in send
[2025-07-13T19:21:53.901+0000] {subprocess.py:106} INFO -     raise ConnectionError(e, request=request)
[2025-07-13T19:21:53.901+0000] {subprocess.py:106} INFO - requests.exceptions.ConnectionError: HTTPConnectionPool(host='127.0.0.1', port=5000): Max retries exceeded with url: /api/2.0/mlflow/experiments/get-by-name?experiment_name=xgboost-hyperopt (Caused by NewConnectionError('<urllib3.connection.HTTPConnection object at 0x7f360b635be0>: Failed to establish a new connection: [Errno 111] Connection refused'))
[2025-07-13T19:21:53.902+0000] {subprocess.py:106} INFO - 
[2025-07-13T19:21:53.902+0000] {subprocess.py:106} INFO - During handling of the above exception, another exception occurred:
[2025-07-13T19:21:53.902+0000] {subprocess.py:106} INFO - 
[2025-07-13T19:21:53.903+0000] {subprocess.py:106} INFO - Traceback (most recent call last):
[2025-07-13T19:21:53.904+0000] {subprocess.py:106} INFO -   File "/opt/***/pipeline/train_register.py", line 23, in <module>
[2025-07-13T19:21:53.904+0000] {subprocess.py:106} INFO -     exp = client.get_experiment_by_name(EXPERIMENT_HYPEROPT)
[2025-07-13T19:21:53.905+0000] {subprocess.py:106} INFO -           ^^^^^^^^^^^^^^^^^^^^^^^^^^^^^^^^^^^^^^^^^^^^^^^^^^
[2025-07-13T19:21:53.905+0000] {subprocess.py:106} INFO -   File "/home/***/.local/lib/python3.12/site-packages/mlflow/tracking/client.py", line 1747, in get_experiment_by_name
[2025-07-13T19:21:53.906+0000] {subprocess.py:106} INFO -     return self._tracking_client.get_experiment_by_name(name)
[2025-07-13T19:21:53.907+0000] {subprocess.py:106} INFO -            ^^^^^^^^^^^^^^^^^^^^^^^^^^^^^^^^^^^^^^^^^^^^^^^^^^
[2025-07-13T19:21:53.909+0000] {subprocess.py:106} INFO -   File "/home/***/.local/lib/python3.12/site-packages/mlflow/tracking/_tracking_service/client.py", line 258, in get_experiment_by_name
[2025-07-13T19:21:53.911+0000] {subprocess.py:106} INFO -     return self.store.get_experiment_by_name(name)
[2025-07-13T19:21:53.912+0000] {subprocess.py:106} INFO -            ^^^^^^^^^^^^^^^^^^^^^^^^^^^^^^^^^^^^^^^
[2025-07-13T19:21:53.913+0000] {subprocess.py:106} INFO -   File "/home/***/.local/lib/python3.12/site-packages/mlflow/store/tracking/rest_store.py", line 869, in get_experiment_by_name
[2025-07-13T19:21:53.914+0000] {subprocess.py:106} INFO -     response_proto = self._call_endpoint(GetExperimentByName, req_body)
[2025-07-13T19:21:53.915+0000] {subprocess.py:106} INFO -                      ^^^^^^^^^^^^^^^^^^^^^^^^^^^^^^^^^^^^^^^^^^^^^^^^^^
[2025-07-13T19:21:53.915+0000] {subprocess.py:106} INFO -   File "/home/***/.local/lib/python3.12/site-packages/mlflow/store/tracking/rest_store.py", line 135, in _call_endpoint
[2025-07-13T19:21:53.917+0000] {subprocess.py:106} INFO -     return call_endpoint(
[2025-07-13T19:21:53.918+0000] {subprocess.py:106} INFO -            ^^^^^^^^^^^^^^
[2025-07-13T19:21:53.918+0000] {subprocess.py:106} INFO -   File "/home/***/.local/lib/python3.12/site-packages/mlflow/utils/rest_utils.py", line 585, in call_endpoint
[2025-07-13T19:21:53.919+0000] {subprocess.py:106} INFO -     response = http_request(**call_kwargs)
[2025-07-13T19:21:53.920+0000] {subprocess.py:106} INFO -                ^^^^^^^^^^^^^^^^^^^^^^^^^^^
[2025-07-13T19:21:53.920+0000] {subprocess.py:106} INFO -   File "/home/***/.local/lib/python3.12/site-packages/mlflow/utils/rest_utils.py", line 252, in http_request
[2025-07-13T19:21:53.932+0000] {subprocess.py:106} INFO -     raise MlflowException(f"API request to {url} failed with exception {e}")
[2025-07-13T19:21:53.933+0000] {subprocess.py:106} INFO - mlflow.exceptions.MlflowException: API request to http://127.0.0.1:5000/api/2.0/mlflow/experiments/get-by-name failed with exception HTTPConnectionPool(host='127.0.0.1', port=5000): Max retries exceeded with url: /api/2.0/mlflow/experiments/get-by-name?experiment_name=xgboost-hyperopt (Caused by NewConnectionError('<urllib3.connection.HTTPConnection object at 0x7f360b635be0>: Failed to establish a new connection: [Errno 111] Connection refused'))
[2025-07-13T19:21:54.603+0000] {subprocess.py:110} INFO - Command exited with return code 1
[2025-07-13T19:21:54.647+0000] {taskinstance.py:3313} ERROR - Task failed with exception
Traceback (most recent call last):
  File "/home/airflow/.local/lib/python3.12/site-packages/airflow/models/taskinstance.py", line 768, in _execute_task
    result = _execute_callable(context=context, **execute_callable_kwargs)
             ^^^^^^^^^^^^^^^^^^^^^^^^^^^^^^^^^^^^^^^^^^^^^^^^^^^^^^^^^^^^^
  File "/home/airflow/.local/lib/python3.12/site-packages/airflow/models/taskinstance.py", line 734, in _execute_callable
    return ExecutionCallableRunner(
           ^^^^^^^^^^^^^^^^^^^^^^^^
  File "/home/airflow/.local/lib/python3.12/site-packages/airflow/utils/operator_helpers.py", line 252, in run
    return self.func(*args, **kwargs)
           ^^^^^^^^^^^^^^^^^^^^^^^^^^
  File "/home/airflow/.local/lib/python3.12/site-packages/airflow/models/baseoperator.py", line 424, in wrapper
    return func(self, *args, **kwargs)
           ^^^^^^^^^^^^^^^^^^^^^^^^^^^
  File "/home/airflow/.local/lib/python3.12/site-packages/airflow/operators/bash.py", line 276, in execute
    raise AirflowException(
airflow.exceptions.AirflowException: Bash command failed. The command returned a non-zero exit code 1.
[2025-07-13T19:21:54.658+0000] {taskinstance.py:1226} INFO - Marking task as FAILED. dag_id=turnstile_ml_pipeline, task_id=train_model, run_id=manual__2025-07-13T17:16:28+00:00, execution_date=20250713T171628, start_date=20250713T191737, end_date=20250713T192154
[2025-07-13T19:21:54.738+0000] {taskinstance.py:341} INFO - ::group::Post task execution logs
[2025-07-13T19:21:54.742+0000] {standard_task_runner.py:124} ERROR - Failed to execute job 11 for task train_model (Bash command failed. The command returned a non-zero exit code 1.; 460)
Traceback (most recent call last):
  File "/home/airflow/.local/lib/python3.12/site-packages/airflow/task/task_runner/standard_task_runner.py", line 117, in _start_by_fork
    ret = args.func(args, dag=self.dag)
          ^^^^^^^^^^^^^^^^^^^^^^^^^^^^^
  File "/home/airflow/.local/lib/python3.12/site-packages/airflow/cli/cli_config.py", line 49, in command
    return func(*args, **kwargs)
           ^^^^^^^^^^^^^^^^^^^^^
  File "/home/airflow/.local/lib/python3.12/site-packages/airflow/utils/cli.py", line 116, in wrapper
    return f(*args, **kwargs)
           ^^^^^^^^^^^^^^^^^^
  File "/home/airflow/.local/lib/python3.12/site-packages/airflow/cli/commands/task_command.py", line 483, in task_run
    task_return_code = _run_task_by_selected_method(args, _dag, ti)
                       ^^^^^^^^^^^^^^^^^^^^^^^^^^^^^^^^^^^^^^^^^^^^
  File "/home/airflow/.local/lib/python3.12/site-packages/airflow/cli/commands/task_command.py", line 256, in _run_task_by_selected_method
    return _run_raw_task(args, ti)
           ^^^^^^^^^^^^^^^^^^^^^^^
  File "/home/airflow/.local/lib/python3.12/site-packages/airflow/cli/commands/task_command.py", line 341, in _run_raw_task
    return ti._run_raw_task(
           ^^^^^^^^^^^^^^^^^
  File "/home/airflow/.local/lib/python3.12/site-packages/airflow/utils/session.py", line 97, in wrapper
    return func(*args, session=session, **kwargs)
           ^^^^^^^^^^^^^^^^^^^^^^^^^^^^^^^^^^^^^^
  File "/home/airflow/.local/lib/python3.12/site-packages/airflow/models/taskinstance.py", line 3006, in _run_raw_task
    return _run_raw_task(
           ^^^^^^^^^^^^^^
  File "/home/airflow/.local/lib/python3.12/site-packages/airflow/models/taskinstance.py", line 274, in _run_raw_task
    TaskInstance._execute_task_with_callbacks(
  File "/home/airflow/.local/lib/python3.12/site-packages/airflow/models/taskinstance.py", line 3161, in _execute_task_with_callbacks
    result = self._execute_task(context, task_orig)
             ^^^^^^^^^^^^^^^^^^^^^^^^^^^^^^^^^^^^^^
  File "/home/airflow/.local/lib/python3.12/site-packages/airflow/models/taskinstance.py", line 3185, in _execute_task
    return _execute_task(self, context, task_orig)
           ^^^^^^^^^^^^^^^^^^^^^^^^^^^^^^^^^^^^^^^
  File "/home/airflow/.local/lib/python3.12/site-packages/airflow/models/taskinstance.py", line 768, in _execute_task
    result = _execute_callable(context=context, **execute_callable_kwargs)
             ^^^^^^^^^^^^^^^^^^^^^^^^^^^^^^^^^^^^^^^^^^^^^^^^^^^^^^^^^^^^^
  File "/home/airflow/.local/lib/python3.12/site-packages/airflow/models/taskinstance.py", line 734, in _execute_callable
    return ExecutionCallableRunner(
           ^^^^^^^^^^^^^^^^^^^^^^^^
  File "/home/airflow/.local/lib/python3.12/site-packages/airflow/utils/operator_helpers.py", line 252, in run
    return self.func(*args, **kwargs)
           ^^^^^^^^^^^^^^^^^^^^^^^^^^
  File "/home/airflow/.local/lib/python3.12/site-packages/airflow/models/baseoperator.py", line 424, in wrapper
    return func(self, *args, **kwargs)
           ^^^^^^^^^^^^^^^^^^^^^^^^^^^
  File "/home/airflow/.local/lib/python3.12/site-packages/airflow/operators/bash.py", line 276, in execute
    raise AirflowException(
airflow.exceptions.AirflowException: Bash command failed. The command returned a non-zero exit code 1.
[2025-07-13T19:21:54.791+0000] {local_task_job_runner.py:266} INFO - Task exited with return code 1
[2025-07-13T19:21:54.842+0000] {taskinstance.py:3901} INFO - 0 downstream tasks scheduled from follow-on schedule check
[2025-07-13T19:21:54.860+0000] {local_task_job_runner.py:245} INFO - ::endgroup::
