[2025-07-07T17:06:20.558+0000] {logging_mixin.py:154} INFO - Changing /opt/***/logs/dag_id=turnstile_ml_pipeline/run_id=manual__2025-07-07T17:06:08+00:00/task_id=download_and_ingest permission to 509
[2025-07-07T17:06:20.559+0000] {logging_mixin.py:154} INFO - Failed to change /opt/***/logs/dag_id=turnstile_ml_pipeline/run_id=manual__2025-07-07T17:06:08+00:00/task_id=download_and_ingest permission to 509: [Errno 1] Operation not permitted: '/opt/***/logs/dag_id=turnstile_ml_pipeline/run_id=manual__2025-07-07T17:06:08+00:00/task_id=download_and_ingest'
[2025-07-07T17:06:20.620+0000] {logging_mixin.py:154} INFO - Changing /opt/***/logs/dag_id=turnstile_ml_pipeline/run_id=manual__2025-07-07T17:06:08+00:00/task_id=download_and_ingest permission to 509
[2025-07-07T17:06:20.621+0000] {logging_mixin.py:154} INFO - Failed to change /opt/***/logs/dag_id=turnstile_ml_pipeline/run_id=manual__2025-07-07T17:06:08+00:00/task_id=download_and_ingest permission to 509: [Errno 1] Operation not permitted: '/opt/***/logs/dag_id=turnstile_ml_pipeline/run_id=manual__2025-07-07T17:06:08+00:00/task_id=download_and_ingest'
[2025-07-07T17:06:20.675+0000] {taskinstance.py:1159} INFO - Dependencies all met for dep_context=non-requeueable deps ti=<TaskInstance: turnstile_ml_pipeline.download_and_ingest manual__2025-07-07T17:06:08+00:00 [queued]>
[2025-07-07T17:06:20.688+0000] {taskinstance.py:1159} INFO - Dependencies all met for dep_context=requeueable deps ti=<TaskInstance: turnstile_ml_pipeline.download_and_ingest manual__2025-07-07T17:06:08+00:00 [queued]>
[2025-07-07T17:06:20.689+0000] {taskinstance.py:1361} INFO - Starting attempt 1 of 1
[2025-07-07T17:06:20.707+0000] {taskinstance.py:1382} INFO - Executing <Task(BashOperator): download_and_ingest> on 2025-07-07 17:06:08+00:00
[2025-07-07T17:06:20.714+0000] {standard_task_runner.py:57} INFO - Started process 35 to run task
[2025-07-07T17:06:20.718+0000] {standard_task_runner.py:84} INFO - Running: ['***', 'tasks', 'run', 'turnstile_ml_pipeline', 'download_and_ingest', 'manual__2025-07-07T17:06:08+00:00', '--job-id', '23', '--raw', '--subdir', 'DAGS_FOLDER/pipeline_dag.py', '--cfg-path', '/tmp/tmpy84wdq8m']
[2025-07-07T17:06:20.720+0000] {standard_task_runner.py:85} INFO - Job 23: Subtask download_and_ingest
[2025-07-07T17:06:20.744+0000] {logging_mixin.py:154} WARNING - /home/***/.local/lib/python3.8/site-packages/***/settings.py:195 DeprecationWarning: The sql_alchemy_conn option in [core] has been moved to the sql_alchemy_conn option in [database] - the old setting has been used, but please update your config.
[2025-07-07T17:06:20.803+0000] {logging_mixin.py:154} INFO - Changing /opt/***/logs/dag_id=turnstile_ml_pipeline/run_id=manual__2025-07-07T17:06:08+00:00/task_id=download_and_ingest permission to 509
[2025-07-07T17:06:20.804+0000] {logging_mixin.py:154} INFO - Failed to change /opt/***/logs/dag_id=turnstile_ml_pipeline/run_id=manual__2025-07-07T17:06:08+00:00/task_id=download_and_ingest permission to 509: [Errno 1] Operation not permitted: '/opt/***/logs/dag_id=turnstile_ml_pipeline/run_id=manual__2025-07-07T17:06:08+00:00/task_id=download_and_ingest'
[2025-07-07T17:06:20.807+0000] {task_command.py:416} INFO - Running <TaskInstance: turnstile_ml_pipeline.download_and_ingest manual__2025-07-07T17:06:08+00:00 [running]> on host 7797eb5ba5f9
[2025-07-07T17:06:20.927+0000] {taskinstance.py:1662} INFO - Exporting env vars: AIRFLOW_CTX_DAG_OWNER='***' AIRFLOW_CTX_DAG_ID='turnstile_ml_pipeline' AIRFLOW_CTX_TASK_ID='download_and_ingest' AIRFLOW_CTX_EXECUTION_DATE='2025-07-07T17:06:08+00:00' AIRFLOW_CTX_TRY_NUMBER='1' AIRFLOW_CTX_DAG_RUN_ID='manual__2025-07-07T17:06:08+00:00'
[2025-07-07T17:06:20.929+0000] {subprocess.py:63} INFO - Tmp dir root location: /tmp
[2025-07-07T17:06:20.931+0000] {subprocess.py:75} INFO - Running command: ['/bin/bash', '-c', '\n            python /opt/***/pipeline/download_ingest.py                 --year 2022                 --month 6                 --start_day 22                 --end_day 23                 --user ***                 --password ***                 --host postgres                 --port 5432                 --db_name ny_sub_turnstiles                 --table_name raw_turnstile_data\n        ']
[2025-07-07T17:06:20.942+0000] {subprocess.py:86} INFO - Output:
[2025-07-07T17:06:24.995+0000] {subprocess.py:93} INFO - [INFO] Fetching data for dates: ['2022-06-22', '2022-06-23']
[2025-07-07T17:06:25.012+0000] {subprocess.py:93} INFO - Traceback (most recent call last):
[2025-07-07T17:06:25.013+0000] {subprocess.py:93} INFO -   File "/home/***/.local/lib/python3.8/site-packages/sqlalchemy/engine/base.py", line 3371, in _wrap_pool_connect
[2025-07-07T17:06:25.014+0000] {subprocess.py:93} INFO -     return fn()
[2025-07-07T17:06:25.014+0000] {subprocess.py:93} INFO -   File "/home/***/.local/lib/python3.8/site-packages/sqlalchemy/pool/base.py", line 327, in connect
[2025-07-07T17:06:25.015+0000] {subprocess.py:93} INFO -     return _ConnectionFairy._checkout(self)
[2025-07-07T17:06:25.015+0000] {subprocess.py:93} INFO -   File "/home/***/.local/lib/python3.8/site-packages/sqlalchemy/pool/base.py", line 894, in _checkout
[2025-07-07T17:06:25.016+0000] {subprocess.py:93} INFO -     fairy = _ConnectionRecord.checkout(pool)
[2025-07-07T17:06:25.017+0000] {subprocess.py:93} INFO -   File "/home/***/.local/lib/python3.8/site-packages/sqlalchemy/pool/base.py", line 493, in checkout
[2025-07-07T17:06:25.017+0000] {subprocess.py:93} INFO -     rec = pool._do_get()
[2025-07-07T17:06:25.018+0000] {subprocess.py:93} INFO -   File "/home/***/.local/lib/python3.8/site-packages/sqlalchemy/pool/impl.py", line 146, in _do_get
[2025-07-07T17:06:25.018+0000] {subprocess.py:93} INFO -     self._dec_overflow()
[2025-07-07T17:06:25.019+0000] {subprocess.py:93} INFO -   File "/home/***/.local/lib/python3.8/site-packages/sqlalchemy/util/langhelpers.py", line 70, in __exit__
[2025-07-07T17:06:25.019+0000] {subprocess.py:93} INFO -     compat.raise_(
[2025-07-07T17:06:25.020+0000] {subprocess.py:93} INFO -   File "/home/***/.local/lib/python3.8/site-packages/sqlalchemy/util/compat.py", line 211, in raise_
[2025-07-07T17:06:25.020+0000] {subprocess.py:93} INFO -     raise exception
[2025-07-07T17:06:25.021+0000] {subprocess.py:93} INFO -   File "/home/***/.local/lib/python3.8/site-packages/sqlalchemy/pool/impl.py", line 143, in _do_get
[2025-07-07T17:06:25.021+0000] {subprocess.py:93} INFO -     return self._create_connection()
[2025-07-07T17:06:25.021+0000] {subprocess.py:93} INFO -   File "/home/***/.local/lib/python3.8/site-packages/sqlalchemy/pool/base.py", line 273, in _create_connection
[2025-07-07T17:06:25.022+0000] {subprocess.py:93} INFO -     return _ConnectionRecord(self)
[2025-07-07T17:06:25.022+0000] {subprocess.py:93} INFO -   File "/home/***/.local/lib/python3.8/site-packages/sqlalchemy/pool/base.py", line 388, in __init__
[2025-07-07T17:06:25.023+0000] {subprocess.py:93} INFO -     self.__connect()
[2025-07-07T17:06:25.023+0000] {subprocess.py:93} INFO -   File "/home/***/.local/lib/python3.8/site-packages/sqlalchemy/pool/base.py", line 691, in __connect
[2025-07-07T17:06:25.023+0000] {subprocess.py:93} INFO -     pool.logger.debug("Error on connect(): %s", e)
[2025-07-07T17:06:25.024+0000] {subprocess.py:93} INFO -   File "/home/***/.local/lib/python3.8/site-packages/sqlalchemy/util/langhelpers.py", line 70, in __exit__
[2025-07-07T17:06:25.024+0000] {subprocess.py:93} INFO -     compat.raise_(
[2025-07-07T17:06:25.025+0000] {subprocess.py:93} INFO -   File "/home/***/.local/lib/python3.8/site-packages/sqlalchemy/util/compat.py", line 211, in raise_
[2025-07-07T17:06:25.025+0000] {subprocess.py:93} INFO -     raise exception
[2025-07-07T17:06:25.026+0000] {subprocess.py:93} INFO -   File "/home/***/.local/lib/python3.8/site-packages/sqlalchemy/pool/base.py", line 686, in __connect
[2025-07-07T17:06:25.026+0000] {subprocess.py:93} INFO -     self.dbapi_connection = connection = pool._invoke_creator(self)
[2025-07-07T17:06:25.027+0000] {subprocess.py:93} INFO -   File "/home/***/.local/lib/python3.8/site-packages/sqlalchemy/engine/create.py", line 574, in connect
[2025-07-07T17:06:25.027+0000] {subprocess.py:93} INFO -     return dialect.connect(*cargs, **cparams)
[2025-07-07T17:06:25.028+0000] {subprocess.py:93} INFO -   File "/home/***/.local/lib/python3.8/site-packages/sqlalchemy/engine/default.py", line 598, in connect
[2025-07-07T17:06:25.028+0000] {subprocess.py:93} INFO -     return self.dbapi.connect(*cargs, **cparams)
[2025-07-07T17:06:25.029+0000] {subprocess.py:93} INFO -   File "/home/***/.local/lib/python3.8/site-packages/psycopg2/__init__.py", line 122, in connect
[2025-07-07T17:06:25.029+0000] {subprocess.py:93} INFO -     conn = _connect(dsn, connection_factory=connection_factory, **kwasync)
[2025-07-07T17:06:25.030+0000] {subprocess.py:93} INFO - psycopg2.OperationalError: connection to server at "postgres" (172.21.0.4), port 5432 failed: FATAL:  database "ny_sub_turnstiles" does not exist
[2025-07-07T17:06:25.030+0000] {subprocess.py:93} INFO - 
[2025-07-07T17:06:25.031+0000] {subprocess.py:93} INFO - 
[2025-07-07T17:06:25.031+0000] {subprocess.py:93} INFO - The above exception was the direct cause of the following exception:
[2025-07-07T17:06:25.032+0000] {subprocess.py:93} INFO - 
[2025-07-07T17:06:25.032+0000] {subprocess.py:93} INFO - Traceback (most recent call last):
[2025-07-07T17:06:25.033+0000] {subprocess.py:93} INFO -   File "/opt/***/pipeline/download_ingest.py", line 58, in <module>
[2025-07-07T17:06:25.034+0000] {subprocess.py:93} INFO -     download_and_ingest(**vars(args))
[2025-07-07T17:06:25.034+0000] {subprocess.py:93} INFO -   File "/opt/***/pipeline/download_ingest.py", line 41, in download_and_ingest
[2025-07-07T17:06:25.035+0000] {subprocess.py:93} INFO -     df_raw.to_sql(name=table_name, con=engine, if_exists="replace", index=False)
[2025-07-07T17:06:25.035+0000] {subprocess.py:93} INFO -   File "/home/***/.local/lib/python3.8/site-packages/pandas/core/generic.py", line 2878, in to_sql
[2025-07-07T17:06:25.036+0000] {subprocess.py:93} INFO -     return sql.to_sql(
[2025-07-07T17:06:25.037+0000] {subprocess.py:93} INFO -   File "/home/***/.local/lib/python3.8/site-packages/pandas/io/sql.py", line 768, in to_sql
[2025-07-07T17:06:25.037+0000] {subprocess.py:93} INFO -     with pandasSQL_builder(con, schema=schema, need_transaction=True) as pandas_sql:
[2025-07-07T17:06:25.038+0000] {subprocess.py:93} INFO -   File "/home/***/.local/lib/python3.8/site-packages/pandas/io/sql.py", line 832, in pandasSQL_builder
[2025-07-07T17:06:25.038+0000] {subprocess.py:93} INFO -     return SQLDatabase(con, schema, need_transaction)
[2025-07-07T17:06:25.039+0000] {subprocess.py:93} INFO -   File "/home/***/.local/lib/python3.8/site-packages/pandas/io/sql.py", line 1539, in __init__
[2025-07-07T17:06:25.039+0000] {subprocess.py:93} INFO -     con = self.exit_stack.enter_context(con.connect())
[2025-07-07T17:06:25.040+0000] {subprocess.py:93} INFO -   File "/home/***/.local/lib/python3.8/site-packages/sqlalchemy/engine/base.py", line 3325, in connect
[2025-07-07T17:06:25.041+0000] {subprocess.py:93} INFO -     return self._connection_cls(self, close_with_result=close_with_result)
[2025-07-07T17:06:25.041+0000] {subprocess.py:93} INFO -   File "/home/***/.local/lib/python3.8/site-packages/sqlalchemy/engine/base.py", line 96, in __init__
[2025-07-07T17:06:25.042+0000] {subprocess.py:93} INFO -     else engine.raw_connection()
[2025-07-07T17:06:25.042+0000] {subprocess.py:93} INFO -   File "/home/***/.local/lib/python3.8/site-packages/sqlalchemy/engine/base.py", line 3404, in raw_connection
[2025-07-07T17:06:25.042+0000] {subprocess.py:93} INFO -     return self._wrap_pool_connect(self.pool.connect, _connection)
[2025-07-07T17:06:25.043+0000] {subprocess.py:93} INFO -   File "/home/***/.local/lib/python3.8/site-packages/sqlalchemy/engine/base.py", line 3374, in _wrap_pool_connect
[2025-07-07T17:06:25.043+0000] {subprocess.py:93} INFO -     Connection._handle_dbapi_exception_noconnection(
[2025-07-07T17:06:25.044+0000] {subprocess.py:93} INFO -   File "/home/***/.local/lib/python3.8/site-packages/sqlalchemy/engine/base.py", line 2208, in _handle_dbapi_exception_noconnection
[2025-07-07T17:06:25.044+0000] {subprocess.py:93} INFO -     util.raise_(
[2025-07-07T17:06:25.045+0000] {subprocess.py:93} INFO -   File "/home/***/.local/lib/python3.8/site-packages/sqlalchemy/util/compat.py", line 211, in raise_
[2025-07-07T17:06:25.045+0000] {subprocess.py:93} INFO -     raise exception
[2025-07-07T17:06:25.046+0000] {subprocess.py:93} INFO -   File "/home/***/.local/lib/python3.8/site-packages/sqlalchemy/engine/base.py", line 3371, in _wrap_pool_connect
[2025-07-07T17:06:25.046+0000] {subprocess.py:93} INFO -     return fn()
[2025-07-07T17:06:25.047+0000] {subprocess.py:93} INFO -   File "/home/***/.local/lib/python3.8/site-packages/sqlalchemy/pool/base.py", line 327, in connect
[2025-07-07T17:06:25.048+0000] {subprocess.py:93} INFO -     return _ConnectionFairy._checkout(self)
[2025-07-07T17:06:25.048+0000] {subprocess.py:93} INFO -   File "/home/***/.local/lib/python3.8/site-packages/sqlalchemy/pool/base.py", line 894, in _checkout
[2025-07-07T17:06:25.049+0000] {subprocess.py:93} INFO -     fairy = _ConnectionRecord.checkout(pool)
[2025-07-07T17:06:25.049+0000] {subprocess.py:93} INFO -   File "/home/***/.local/lib/python3.8/site-packages/sqlalchemy/pool/base.py", line 493, in checkout
[2025-07-07T17:06:25.050+0000] {subprocess.py:93} INFO -     rec = pool._do_get()
[2025-07-07T17:06:25.050+0000] {subprocess.py:93} INFO -   File "/home/***/.local/lib/python3.8/site-packages/sqlalchemy/pool/impl.py", line 146, in _do_get
[2025-07-07T17:06:25.051+0000] {subprocess.py:93} INFO -     self._dec_overflow()
[2025-07-07T17:06:25.051+0000] {subprocess.py:93} INFO -   File "/home/***/.local/lib/python3.8/site-packages/sqlalchemy/util/langhelpers.py", line 70, in __exit__
[2025-07-07T17:06:25.052+0000] {subprocess.py:93} INFO -     compat.raise_(
[2025-07-07T17:06:25.052+0000] {subprocess.py:93} INFO -   File "/home/***/.local/lib/python3.8/site-packages/sqlalchemy/util/compat.py", line 211, in raise_
[2025-07-07T17:06:25.053+0000] {subprocess.py:93} INFO -     raise exception
[2025-07-07T17:06:25.053+0000] {subprocess.py:93} INFO -   File "/home/***/.local/lib/python3.8/site-packages/sqlalchemy/pool/impl.py", line 143, in _do_get
[2025-07-07T17:06:25.053+0000] {subprocess.py:93} INFO -     return self._create_connection()
[2025-07-07T17:06:25.054+0000] {subprocess.py:93} INFO -   File "/home/***/.local/lib/python3.8/site-packages/sqlalchemy/pool/base.py", line 273, in _create_connection
[2025-07-07T17:06:25.054+0000] {subprocess.py:93} INFO -     return _ConnectionRecord(self)
[2025-07-07T17:06:25.055+0000] {subprocess.py:93} INFO -   File "/home/***/.local/lib/python3.8/site-packages/sqlalchemy/pool/base.py", line 388, in __init__
[2025-07-07T17:06:25.055+0000] {subprocess.py:93} INFO -     self.__connect()
[2025-07-07T17:06:25.056+0000] {subprocess.py:93} INFO -   File "/home/***/.local/lib/python3.8/site-packages/sqlalchemy/pool/base.py", line 691, in __connect
[2025-07-07T17:06:25.056+0000] {subprocess.py:93} INFO -     pool.logger.debug("Error on connect(): %s", e)
[2025-07-07T17:06:25.057+0000] {subprocess.py:93} INFO -   File "/home/***/.local/lib/python3.8/site-packages/sqlalchemy/util/langhelpers.py", line 70, in __exit__
[2025-07-07T17:06:25.057+0000] {subprocess.py:93} INFO -     compat.raise_(
[2025-07-07T17:06:25.058+0000] {subprocess.py:93} INFO -   File "/home/***/.local/lib/python3.8/site-packages/sqlalchemy/util/compat.py", line 211, in raise_
[2025-07-07T17:06:25.058+0000] {subprocess.py:93} INFO -     raise exception
[2025-07-07T17:06:25.058+0000] {subprocess.py:93} INFO -   File "/home/***/.local/lib/python3.8/site-packages/sqlalchemy/pool/base.py", line 686, in __connect
[2025-07-07T17:06:25.059+0000] {subprocess.py:93} INFO -     self.dbapi_connection = connection = pool._invoke_creator(self)
[2025-07-07T17:06:25.059+0000] {subprocess.py:93} INFO -   File "/home/***/.local/lib/python3.8/site-packages/sqlalchemy/engine/create.py", line 574, in connect
[2025-07-07T17:06:25.060+0000] {subprocess.py:93} INFO -     return dialect.connect(*cargs, **cparams)
[2025-07-07T17:06:25.060+0000] {subprocess.py:93} INFO -   File "/home/***/.local/lib/python3.8/site-packages/sqlalchemy/engine/default.py", line 598, in connect
[2025-07-07T17:06:25.061+0000] {subprocess.py:93} INFO -     return self.dbapi.connect(*cargs, **cparams)
[2025-07-07T17:06:25.061+0000] {subprocess.py:93} INFO -   File "/home/***/.local/lib/python3.8/site-packages/psycopg2/__init__.py", line 122, in connect
[2025-07-07T17:06:25.061+0000] {subprocess.py:93} INFO -     conn = _connect(dsn, connection_factory=connection_factory, **kwasync)
[2025-07-07T17:06:25.062+0000] {subprocess.py:93} INFO - sqlalchemy.exc.OperationalError: (psycopg2.OperationalError) connection to server at "postgres" (172.21.0.4), port 5432 failed: FATAL:  database "ny_sub_turnstiles" does not exist
[2025-07-07T17:06:25.062+0000] {subprocess.py:93} INFO - 
[2025-07-07T17:06:25.063+0000] {subprocess.py:93} INFO - (Background on this error at: https://sqlalche.me/e/14/e3q8)
[2025-07-07T17:06:25.142+0000] {subprocess.py:97} INFO - Command exited with return code 1
[2025-07-07T17:06:25.158+0000] {taskinstance.py:1937} ERROR - Task failed with exception
Traceback (most recent call last):
  File "/home/airflow/.local/lib/python3.8/site-packages/airflow/operators/bash.py", line 210, in execute
    raise AirflowException(
airflow.exceptions.AirflowException: Bash command failed. The command returned a non-zero exit code 1.
[2025-07-07T17:06:25.164+0000] {taskinstance.py:1400} INFO - Marking task as FAILED. dag_id=turnstile_ml_pipeline, task_id=download_and_ingest, execution_date=20250707T170608, start_date=20250707T170620, end_date=20250707T170625
[2025-07-07T17:06:25.184+0000] {standard_task_runner.py:104} ERROR - Failed to execute job 23 for task download_and_ingest (Bash command failed. The command returned a non-zero exit code 1.; 35)
[2025-07-07T17:06:25.200+0000] {local_task_job_runner.py:228} INFO - Task exited with return code 1
[2025-07-07T17:06:25.236+0000] {taskinstance.py:2778} INFO - 0 downstream tasks scheduled from follow-on schedule check
