[2025-08-05T14:44:40.895+0000] {local_task_job_runner.py:123} INFO - ::group::Pre task execution logs
[2025-08-05T14:44:40.919+0000] {taskinstance.py:2614} INFO - Dependencies all met for dep_context=non-requeueable deps ti=<TaskInstance: turnstile_ml_pipeline.run_inference scheduled__2025-08-04T00:00:00+00:00 [queued]>
[2025-08-05T14:44:40.930+0000] {taskinstance.py:2614} INFO - Dependencies all met for dep_context=requeueable deps ti=<TaskInstance: turnstile_ml_pipeline.run_inference scheduled__2025-08-04T00:00:00+00:00 [queued]>
[2025-08-05T14:44:40.931+0000] {taskinstance.py:2867} INFO - Starting attempt 1 of 1
[2025-08-05T14:44:40.948+0000] {taskinstance.py:2890} INFO - Executing <Task(BashOperator): run_inference> on 2025-08-04 00:00:00+00:00
[2025-08-05T14:44:40.956+0000] {standard_task_runner.py:72} INFO - Started process 287 to run task
[2025-08-05T14:44:40.960+0000] {standard_task_runner.py:104} INFO - Running: ['***', 'tasks', 'run', 'turnstile_ml_pipeline', 'run_inference', 'scheduled__2025-08-04T00:00:00+00:00', '--job-id', '100', '--raw', '--subdir', 'DAGS_FOLDER/turnstile_ml_pipeline.py', '--cfg-path', '/tmp/tmpb1gsexr0']
[2025-08-05T14:44:40.963+0000] {standard_task_runner.py:105} INFO - Job 100: Subtask run_inference
[2025-08-05T14:44:40.980+0000] {logging_mixin.py:190} WARNING - /home/***/.local/lib/python3.12/site-packages/***/settings.py:209 DeprecationWarning: The sql_alchemy_conn option in [core] has been moved to the sql_alchemy_conn option in [database] - the old setting has been used, but please update your config.
[2025-08-05T14:44:41.033+0000] {task_command.py:467} INFO - Running <TaskInstance: turnstile_ml_pipeline.run_inference scheduled__2025-08-04T00:00:00+00:00 [running]> on host c3acc3669c6c
[2025-08-05T14:44:41.037+0000] {logging_mixin.py:190} WARNING - /home/***/.local/lib/python3.12/site-packages/***/settings.py:470 DeprecationWarning: The sql_alchemy_conn option in [core] has been moved to the sql_alchemy_conn option in [database] - the old setting has been used, but please update your config.
[2025-08-05T14:44:41.159+0000] {taskinstance.py:3134} INFO - Exporting env vars: AIRFLOW_CTX_DAG_OWNER='***' AIRFLOW_CTX_DAG_ID='turnstile_ml_pipeline' AIRFLOW_CTX_TASK_ID='run_inference' AIRFLOW_CTX_EXECUTION_DATE='2025-08-04T00:00:00+00:00' AIRFLOW_CTX_TRY_NUMBER='1' AIRFLOW_CTX_DAG_RUN_ID='scheduled__2025-08-04T00:00:00+00:00'
[2025-08-05T14:44:41.160+0000] {taskinstance.py:732} INFO - ::endgroup::
[2025-08-05T14:44:41.208+0000] {subprocess.py:78} INFO - Tmp dir root location: /tmp
[2025-08-05T14:44:41.211+0000] {subprocess.py:88} INFO - Running command: ['/usr/bin/bash', '-c', '\n            python /opt/***/pipeline/inference.py                 --user ***                 --password ***                 --host postgres                 --port 5432                 --db_name ny_sub_turnstiles                 --inference_table inference_features                 --predictions_table predictions\n        ']
[2025-08-05T14:44:41.228+0000] {subprocess.py:99} INFO - Output:
[2025-08-05T14:44:44.699+0000] {subprocess.py:106} INFO - /home/***/.local/lib/python3.12/site-packages/xgboost/data.py:1320: UserWarning: Unknown data type: <class 'xgboost.core.DMatrix'>, trying to convert it to csr_matrix
[2025-08-05T14:44:44.700+0000] {subprocess.py:106} INFO -   warnings.warn(
[2025-08-05T14:44:44.701+0000] {subprocess.py:106} INFO - Traceback (most recent call last):
[2025-08-05T14:44:44.702+0000] {subprocess.py:106} INFO -   File "/opt/***/pipeline/inference.py", line 82, in <module>
[2025-08-05T14:44:44.704+0000] {subprocess.py:106} INFO -     predict_and_save(
[2025-08-05T14:44:44.705+0000] {subprocess.py:106} INFO -   File "/opt/***/pipeline/inference.py", line 45, in predict_and_save
[2025-08-05T14:44:44.706+0000] {subprocess.py:106} INFO -     df_pred["predicted_ridership"] = model.predict(dmat)
[2025-08-05T14:44:44.707+0000] {subprocess.py:106} INFO -                                      ^^^^^^^^^^^^^^^^^^^
[2025-08-05T14:44:44.707+0000] {subprocess.py:106} INFO -   File "/home/***/.local/lib/python3.12/site-packages/xgboost/core.py", line 729, in inner_f
[2025-08-05T14:44:44.708+0000] {subprocess.py:106} INFO -     return func(**kwargs)
[2025-08-05T14:44:44.708+0000] {subprocess.py:106} INFO -            ^^^^^^^^^^^^^^
[2025-08-05T14:44:44.709+0000] {subprocess.py:106} INFO -   File "/home/***/.local/lib/python3.12/site-packages/xgboost/sklearn.py", line 1344, in predict
[2025-08-05T14:44:44.709+0000] {subprocess.py:106} INFO -     test = DMatrix(
[2025-08-05T14:44:44.709+0000] {subprocess.py:106} INFO -            ^^^^^^^^
[2025-08-05T14:44:44.710+0000] {subprocess.py:106} INFO -   File "/home/***/.local/lib/python3.12/site-packages/xgboost/core.py", line 729, in inner_f
[2025-08-05T14:44:44.710+0000] {subprocess.py:106} INFO -     return func(**kwargs)
[2025-08-05T14:44:44.711+0000] {subprocess.py:106} INFO -            ^^^^^^^^^^^^^^
[2025-08-05T14:44:44.711+0000] {subprocess.py:106} INFO -   File "/home/***/.local/lib/python3.12/site-packages/xgboost/core.py", line 885, in __init__
[2025-08-05T14:44:44.711+0000] {subprocess.py:106} INFO -     handle, feature_names, feature_types = dispatch_data_backend(
[2025-08-05T14:44:44.711+0000] {subprocess.py:106} INFO -                                            ^^^^^^^^^^^^^^^^^^^^^^
[2025-08-05T14:44:44.712+0000] {subprocess.py:106} INFO -   File "/home/***/.local/lib/python3.12/site-packages/xgboost/data.py", line 1505, in dispatch_data_backend
[2025-08-05T14:44:44.712+0000] {subprocess.py:106} INFO -     raise TypeError("Not supported type for data." + str(type(data)))
[2025-08-05T14:44:44.712+0000] {subprocess.py:106} INFO - TypeError: Not supported type for data.<class 'xgboost.core.DMatrix'>
[2025-08-05T14:44:45.044+0000] {subprocess.py:110} INFO - Command exited with return code 1
[2025-08-05T14:44:45.056+0000] {taskinstance.py:3313} ERROR - Task failed with exception
Traceback (most recent call last):
  File "/home/airflow/.local/lib/python3.12/site-packages/airflow/models/taskinstance.py", line 768, in _execute_task
    result = _execute_callable(context=context, **execute_callable_kwargs)
             ^^^^^^^^^^^^^^^^^^^^^^^^^^^^^^^^^^^^^^^^^^^^^^^^^^^^^^^^^^^^^
  File "/home/airflow/.local/lib/python3.12/site-packages/airflow/models/taskinstance.py", line 734, in _execute_callable
    return ExecutionCallableRunner(
           ^^^^^^^^^^^^^^^^^^^^^^^^
  File "/home/airflow/.local/lib/python3.12/site-packages/airflow/utils/operator_helpers.py", line 252, in run
    return self.func(*args, **kwargs)
           ^^^^^^^^^^^^^^^^^^^^^^^^^^
  File "/home/airflow/.local/lib/python3.12/site-packages/airflow/models/baseoperator.py", line 424, in wrapper
    return func(self, *args, **kwargs)
           ^^^^^^^^^^^^^^^^^^^^^^^^^^^
  File "/home/airflow/.local/lib/python3.12/site-packages/airflow/operators/bash.py", line 276, in execute
    raise AirflowException(
airflow.exceptions.AirflowException: Bash command failed. The command returned a non-zero exit code 1.
[2025-08-05T14:44:45.064+0000] {taskinstance.py:1226} INFO - Marking task as FAILED. dag_id=turnstile_ml_pipeline, task_id=run_inference, run_id=scheduled__2025-08-04T00:00:00+00:00, execution_date=20250804T000000, start_date=20250805T144440, end_date=20250805T144445
[2025-08-05T14:44:45.099+0000] {taskinstance.py:341} INFO - ::group::Post task execution logs
[2025-08-05T14:44:45.101+0000] {standard_task_runner.py:124} ERROR - Failed to execute job 100 for task run_inference (Bash command failed. The command returned a non-zero exit code 1.; 287)
Traceback (most recent call last):
  File "/home/airflow/.local/lib/python3.12/site-packages/airflow/task/task_runner/standard_task_runner.py", line 117, in _start_by_fork
    ret = args.func(args, dag=self.dag)
          ^^^^^^^^^^^^^^^^^^^^^^^^^^^^^
  File "/home/airflow/.local/lib/python3.12/site-packages/airflow/cli/cli_config.py", line 49, in command
    return func(*args, **kwargs)
           ^^^^^^^^^^^^^^^^^^^^^
  File "/home/airflow/.local/lib/python3.12/site-packages/airflow/utils/cli.py", line 116, in wrapper
    return f(*args, **kwargs)
           ^^^^^^^^^^^^^^^^^^
  File "/home/airflow/.local/lib/python3.12/site-packages/airflow/cli/commands/task_command.py", line 483, in task_run
    task_return_code = _run_task_by_selected_method(args, _dag, ti)
                       ^^^^^^^^^^^^^^^^^^^^^^^^^^^^^^^^^^^^^^^^^^^^
  File "/home/airflow/.local/lib/python3.12/site-packages/airflow/cli/commands/task_command.py", line 256, in _run_task_by_selected_method
    return _run_raw_task(args, ti)
           ^^^^^^^^^^^^^^^^^^^^^^^
  File "/home/airflow/.local/lib/python3.12/site-packages/airflow/cli/commands/task_command.py", line 341, in _run_raw_task
    return ti._run_raw_task(
           ^^^^^^^^^^^^^^^^^
  File "/home/airflow/.local/lib/python3.12/site-packages/airflow/utils/session.py", line 97, in wrapper
    return func(*args, session=session, **kwargs)
           ^^^^^^^^^^^^^^^^^^^^^^^^^^^^^^^^^^^^^^
  File "/home/airflow/.local/lib/python3.12/site-packages/airflow/models/taskinstance.py", line 3006, in _run_raw_task
    return _run_raw_task(
           ^^^^^^^^^^^^^^
  File "/home/airflow/.local/lib/python3.12/site-packages/airflow/models/taskinstance.py", line 274, in _run_raw_task
    TaskInstance._execute_task_with_callbacks(
  File "/home/airflow/.local/lib/python3.12/site-packages/airflow/models/taskinstance.py", line 3161, in _execute_task_with_callbacks
    result = self._execute_task(context, task_orig)
             ^^^^^^^^^^^^^^^^^^^^^^^^^^^^^^^^^^^^^^
  File "/home/airflow/.local/lib/python3.12/site-packages/airflow/models/taskinstance.py", line 3185, in _execute_task
    return _execute_task(self, context, task_orig)
           ^^^^^^^^^^^^^^^^^^^^^^^^^^^^^^^^^^^^^^^
  File "/home/airflow/.local/lib/python3.12/site-packages/airflow/models/taskinstance.py", line 768, in _execute_task
    result = _execute_callable(context=context, **execute_callable_kwargs)
             ^^^^^^^^^^^^^^^^^^^^^^^^^^^^^^^^^^^^^^^^^^^^^^^^^^^^^^^^^^^^^
  File "/home/airflow/.local/lib/python3.12/site-packages/airflow/models/taskinstance.py", line 734, in _execute_callable
    return ExecutionCallableRunner(
           ^^^^^^^^^^^^^^^^^^^^^^^^
  File "/home/airflow/.local/lib/python3.12/site-packages/airflow/utils/operator_helpers.py", line 252, in run
    return self.func(*args, **kwargs)
           ^^^^^^^^^^^^^^^^^^^^^^^^^^
  File "/home/airflow/.local/lib/python3.12/site-packages/airflow/models/baseoperator.py", line 424, in wrapper
    return func(self, *args, **kwargs)
           ^^^^^^^^^^^^^^^^^^^^^^^^^^^
  File "/home/airflow/.local/lib/python3.12/site-packages/airflow/operators/bash.py", line 276, in execute
    raise AirflowException(
airflow.exceptions.AirflowException: Bash command failed. The command returned a non-zero exit code 1.
[2025-08-05T14:44:45.123+0000] {local_task_job_runner.py:266} INFO - Task exited with return code 1
[2025-08-05T14:44:45.154+0000] {taskinstance.py:3901} INFO - 0 downstream tasks scheduled from follow-on schedule check
[2025-08-05T14:44:45.162+0000] {local_task_job_runner.py:245} INFO - ::endgroup::
