[2025-07-07T17:01:10.582+0000] {logging_mixin.py:154} INFO - Changing /opt/***/logs/dag_id=turnstile_ml_pipeline/run_id=manual__2025-07-07T17:01:02+00:00/task_id=download_and_ingest permission to 509
[2025-07-07T17:01:10.583+0000] {logging_mixin.py:154} INFO - Failed to change /opt/***/logs/dag_id=turnstile_ml_pipeline/run_id=manual__2025-07-07T17:01:02+00:00/task_id=download_and_ingest permission to 509: [Errno 1] Operation not permitted: '/opt/***/logs/dag_id=turnstile_ml_pipeline/run_id=manual__2025-07-07T17:01:02+00:00/task_id=download_and_ingest'
[2025-07-07T17:01:10.640+0000] {logging_mixin.py:154} INFO - Changing /opt/***/logs/dag_id=turnstile_ml_pipeline/run_id=manual__2025-07-07T17:01:02+00:00/task_id=download_and_ingest permission to 509
[2025-07-07T17:01:10.641+0000] {logging_mixin.py:154} INFO - Failed to change /opt/***/logs/dag_id=turnstile_ml_pipeline/run_id=manual__2025-07-07T17:01:02+00:00/task_id=download_and_ingest permission to 509: [Errno 1] Operation not permitted: '/opt/***/logs/dag_id=turnstile_ml_pipeline/run_id=manual__2025-07-07T17:01:02+00:00/task_id=download_and_ingest'
[2025-07-07T17:01:10.686+0000] {taskinstance.py:1159} INFO - Dependencies all met for dep_context=non-requeueable deps ti=<TaskInstance: turnstile_ml_pipeline.download_and_ingest manual__2025-07-07T17:01:02+00:00 [queued]>
[2025-07-07T17:01:10.697+0000] {taskinstance.py:1159} INFO - Dependencies all met for dep_context=requeueable deps ti=<TaskInstance: turnstile_ml_pipeline.download_and_ingest manual__2025-07-07T17:01:02+00:00 [queued]>
[2025-07-07T17:01:10.698+0000] {taskinstance.py:1361} INFO - Starting attempt 1 of 1
[2025-07-07T17:01:10.714+0000] {taskinstance.py:1382} INFO - Executing <Task(BashOperator): download_and_ingest> on 2025-07-07 17:01:02+00:00
[2025-07-07T17:01:10.720+0000] {standard_task_runner.py:57} INFO - Started process 53 to run task
[2025-07-07T17:01:10.724+0000] {standard_task_runner.py:84} INFO - Running: ['***', 'tasks', 'run', 'turnstile_ml_pipeline', 'download_and_ingest', 'manual__2025-07-07T17:01:02+00:00', '--job-id', '21', '--raw', '--subdir', 'DAGS_FOLDER/pipeline_dag.py', '--cfg-path', '/tmp/tmp3nsv4w3h']
[2025-07-07T17:01:10.726+0000] {standard_task_runner.py:85} INFO - Job 21: Subtask download_and_ingest
[2025-07-07T17:01:10.754+0000] {logging_mixin.py:154} WARNING - /home/***/.local/lib/python3.8/site-packages/***/settings.py:195 DeprecationWarning: The sql_alchemy_conn option in [core] has been moved to the sql_alchemy_conn option in [database] - the old setting has been used, but please update your config.
[2025-07-07T17:01:10.810+0000] {logging_mixin.py:154} INFO - Changing /opt/***/logs/dag_id=turnstile_ml_pipeline/run_id=manual__2025-07-07T17:01:02+00:00/task_id=download_and_ingest permission to 509
[2025-07-07T17:01:10.811+0000] {logging_mixin.py:154} INFO - Failed to change /opt/***/logs/dag_id=turnstile_ml_pipeline/run_id=manual__2025-07-07T17:01:02+00:00/task_id=download_and_ingest permission to 509: [Errno 1] Operation not permitted: '/opt/***/logs/dag_id=turnstile_ml_pipeline/run_id=manual__2025-07-07T17:01:02+00:00/task_id=download_and_ingest'
[2025-07-07T17:01:10.813+0000] {task_command.py:416} INFO - Running <TaskInstance: turnstile_ml_pipeline.download_and_ingest manual__2025-07-07T17:01:02+00:00 [running]> on host 999302ad868c
[2025-07-07T17:01:10.954+0000] {taskinstance.py:1662} INFO - Exporting env vars: AIRFLOW_CTX_DAG_OWNER='***' AIRFLOW_CTX_DAG_ID='turnstile_ml_pipeline' AIRFLOW_CTX_TASK_ID='download_and_ingest' AIRFLOW_CTX_EXECUTION_DATE='2025-07-07T17:01:02+00:00' AIRFLOW_CTX_TRY_NUMBER='1' AIRFLOW_CTX_DAG_RUN_ID='manual__2025-07-07T17:01:02+00:00'
[2025-07-07T17:01:10.957+0000] {subprocess.py:63} INFO - Tmp dir root location: /tmp
[2025-07-07T17:01:10.959+0000] {subprocess.py:75} INFO - Running command: ['/bin/bash', '-c', '\n            python /opt/***/pipeline/download_ingest.py                 --year 2022                 --month 6                 --start_day 22                 --end_day 23                 --user ***                 --password ***                 --host postgres                 --port 5432                 --db_name ny_sub_turnstiles                 --table_name raw_turnstile_data\n        ']
[2025-07-07T17:01:10.975+0000] {subprocess.py:86} INFO - Output:
[2025-07-07T17:01:24.806+0000] {subprocess.py:93} INFO - [INFO] Fetching data for dates: ['2022-06-22', '2022-06-23']
[2025-07-07T17:01:24.825+0000] {subprocess.py:93} INFO - Traceback (most recent call last):
[2025-07-07T17:01:24.826+0000] {subprocess.py:93} INFO -   File "/home/***/.local/lib/python3.8/site-packages/sqlalchemy/engine/base.py", line 3371, in _wrap_pool_connect
[2025-07-07T17:01:24.826+0000] {subprocess.py:93} INFO -     return fn()
[2025-07-07T17:01:24.827+0000] {subprocess.py:93} INFO -   File "/home/***/.local/lib/python3.8/site-packages/sqlalchemy/pool/base.py", line 327, in connect
[2025-07-07T17:01:24.828+0000] {subprocess.py:93} INFO -     return _ConnectionFairy._checkout(self)
[2025-07-07T17:01:24.829+0000] {subprocess.py:93} INFO -   File "/home/***/.local/lib/python3.8/site-packages/sqlalchemy/pool/base.py", line 894, in _checkout
[2025-07-07T17:01:24.829+0000] {subprocess.py:93} INFO -     fairy = _ConnectionRecord.checkout(pool)
[2025-07-07T17:01:24.830+0000] {subprocess.py:93} INFO -   File "/home/***/.local/lib/python3.8/site-packages/sqlalchemy/pool/base.py", line 493, in checkout
[2025-07-07T17:01:24.831+0000] {subprocess.py:93} INFO -     rec = pool._do_get()
[2025-07-07T17:01:24.831+0000] {subprocess.py:93} INFO -   File "/home/***/.local/lib/python3.8/site-packages/sqlalchemy/pool/impl.py", line 146, in _do_get
[2025-07-07T17:01:24.832+0000] {subprocess.py:93} INFO -     self._dec_overflow()
[2025-07-07T17:01:24.833+0000] {subprocess.py:93} INFO -   File "/home/***/.local/lib/python3.8/site-packages/sqlalchemy/util/langhelpers.py", line 70, in __exit__
[2025-07-07T17:01:24.834+0000] {subprocess.py:93} INFO -     compat.raise_(
[2025-07-07T17:01:24.835+0000] {subprocess.py:93} INFO -   File "/home/***/.local/lib/python3.8/site-packages/sqlalchemy/util/compat.py", line 211, in raise_
[2025-07-07T17:01:24.836+0000] {subprocess.py:93} INFO -     raise exception
[2025-07-07T17:01:24.836+0000] {subprocess.py:93} INFO -   File "/home/***/.local/lib/python3.8/site-packages/sqlalchemy/pool/impl.py", line 143, in _do_get
[2025-07-07T17:01:24.837+0000] {subprocess.py:93} INFO -     return self._create_connection()
[2025-07-07T17:01:24.838+0000] {subprocess.py:93} INFO -   File "/home/***/.local/lib/python3.8/site-packages/sqlalchemy/pool/base.py", line 273, in _create_connection
[2025-07-07T17:01:24.839+0000] {subprocess.py:93} INFO -     return _ConnectionRecord(self)
[2025-07-07T17:01:24.839+0000] {subprocess.py:93} INFO -   File "/home/***/.local/lib/python3.8/site-packages/sqlalchemy/pool/base.py", line 388, in __init__
[2025-07-07T17:01:24.840+0000] {subprocess.py:93} INFO -     self.__connect()
[2025-07-07T17:01:24.841+0000] {subprocess.py:93} INFO -   File "/home/***/.local/lib/python3.8/site-packages/sqlalchemy/pool/base.py", line 691, in __connect
[2025-07-07T17:01:24.842+0000] {subprocess.py:93} INFO -     pool.logger.debug("Error on connect(): %s", e)
[2025-07-07T17:01:24.842+0000] {subprocess.py:93} INFO -   File "/home/***/.local/lib/python3.8/site-packages/sqlalchemy/util/langhelpers.py", line 70, in __exit__
[2025-07-07T17:01:24.843+0000] {subprocess.py:93} INFO -     compat.raise_(
[2025-07-07T17:01:24.844+0000] {subprocess.py:93} INFO -   File "/home/***/.local/lib/python3.8/site-packages/sqlalchemy/util/compat.py", line 211, in raise_
[2025-07-07T17:01:24.845+0000] {subprocess.py:93} INFO -     raise exception
[2025-07-07T17:01:24.846+0000] {subprocess.py:93} INFO -   File "/home/***/.local/lib/python3.8/site-packages/sqlalchemy/pool/base.py", line 686, in __connect
[2025-07-07T17:01:24.846+0000] {subprocess.py:93} INFO -     self.dbapi_connection = connection = pool._invoke_creator(self)
[2025-07-07T17:01:24.847+0000] {subprocess.py:93} INFO -   File "/home/***/.local/lib/python3.8/site-packages/sqlalchemy/engine/create.py", line 574, in connect
[2025-07-07T17:01:24.847+0000] {subprocess.py:93} INFO -     return dialect.connect(*cargs, **cparams)
[2025-07-07T17:01:24.848+0000] {subprocess.py:93} INFO -   File "/home/***/.local/lib/python3.8/site-packages/sqlalchemy/engine/default.py", line 598, in connect
[2025-07-07T17:01:24.849+0000] {subprocess.py:93} INFO -     return self.dbapi.connect(*cargs, **cparams)
[2025-07-07T17:01:24.850+0000] {subprocess.py:93} INFO -   File "/home/***/.local/lib/python3.8/site-packages/psycopg2/__init__.py", line 122, in connect
[2025-07-07T17:01:24.851+0000] {subprocess.py:93} INFO -     conn = _connect(dsn, connection_factory=connection_factory, **kwasync)
[2025-07-07T17:01:24.851+0000] {subprocess.py:93} INFO - psycopg2.OperationalError: connection to server at "postgres" (172.21.0.4), port 5432 failed: FATAL:  database "ny_sub_turnstiles" does not exist
[2025-07-07T17:01:24.852+0000] {subprocess.py:93} INFO - 
[2025-07-07T17:01:24.853+0000] {subprocess.py:93} INFO - 
[2025-07-07T17:01:24.853+0000] {subprocess.py:93} INFO - The above exception was the direct cause of the following exception:
[2025-07-07T17:01:24.854+0000] {subprocess.py:93} INFO - 
[2025-07-07T17:01:24.854+0000] {subprocess.py:93} INFO - Traceback (most recent call last):
[2025-07-07T17:01:24.855+0000] {subprocess.py:93} INFO -   File "/opt/***/pipeline/download_ingest.py", line 58, in <module>
[2025-07-07T17:01:24.856+0000] {subprocess.py:93} INFO -     download_and_ingest(**vars(args))
[2025-07-07T17:01:24.856+0000] {subprocess.py:93} INFO -   File "/opt/***/pipeline/download_ingest.py", line 41, in download_and_ingest
[2025-07-07T17:01:24.857+0000] {subprocess.py:93} INFO -     df_raw.to_sql(name=table_name, con=engine, if_exists="replace", index=False)
[2025-07-07T17:01:24.857+0000] {subprocess.py:93} INFO -   File "/home/***/.local/lib/python3.8/site-packages/pandas/core/generic.py", line 2878, in to_sql
[2025-07-07T17:01:24.858+0000] {subprocess.py:93} INFO -     return sql.to_sql(
[2025-07-07T17:01:24.858+0000] {subprocess.py:93} INFO -   File "/home/***/.local/lib/python3.8/site-packages/pandas/io/sql.py", line 768, in to_sql
[2025-07-07T17:01:24.859+0000] {subprocess.py:93} INFO -     with pandasSQL_builder(con, schema=schema, need_transaction=True) as pandas_sql:
[2025-07-07T17:01:24.860+0000] {subprocess.py:93} INFO -   File "/home/***/.local/lib/python3.8/site-packages/pandas/io/sql.py", line 832, in pandasSQL_builder
[2025-07-07T17:01:24.860+0000] {subprocess.py:93} INFO -     return SQLDatabase(con, schema, need_transaction)
[2025-07-07T17:01:24.861+0000] {subprocess.py:93} INFO -   File "/home/***/.local/lib/python3.8/site-packages/pandas/io/sql.py", line 1539, in __init__
[2025-07-07T17:01:24.861+0000] {subprocess.py:93} INFO -     con = self.exit_stack.enter_context(con.connect())
[2025-07-07T17:01:24.862+0000] {subprocess.py:93} INFO -   File "/home/***/.local/lib/python3.8/site-packages/sqlalchemy/engine/base.py", line 3325, in connect
[2025-07-07T17:01:24.862+0000] {subprocess.py:93} INFO -     return self._connection_cls(self, close_with_result=close_with_result)
[2025-07-07T17:01:24.863+0000] {subprocess.py:93} INFO -   File "/home/***/.local/lib/python3.8/site-packages/sqlalchemy/engine/base.py", line 96, in __init__
[2025-07-07T17:01:24.864+0000] {subprocess.py:93} INFO -     else engine.raw_connection()
[2025-07-07T17:01:24.864+0000] {subprocess.py:93} INFO -   File "/home/***/.local/lib/python3.8/site-packages/sqlalchemy/engine/base.py", line 3404, in raw_connection
[2025-07-07T17:01:24.865+0000] {subprocess.py:93} INFO -     return self._wrap_pool_connect(self.pool.connect, _connection)
[2025-07-07T17:01:24.866+0000] {subprocess.py:93} INFO -   File "/home/***/.local/lib/python3.8/site-packages/sqlalchemy/engine/base.py", line 3374, in _wrap_pool_connect
[2025-07-07T17:01:24.867+0000] {subprocess.py:93} INFO -     Connection._handle_dbapi_exception_noconnection(
[2025-07-07T17:01:24.867+0000] {subprocess.py:93} INFO -   File "/home/***/.local/lib/python3.8/site-packages/sqlalchemy/engine/base.py", line 2208, in _handle_dbapi_exception_noconnection
[2025-07-07T17:01:24.868+0000] {subprocess.py:93} INFO -     util.raise_(
[2025-07-07T17:01:24.869+0000] {subprocess.py:93} INFO -   File "/home/***/.local/lib/python3.8/site-packages/sqlalchemy/util/compat.py", line 211, in raise_
[2025-07-07T17:01:24.870+0000] {subprocess.py:93} INFO -     raise exception
[2025-07-07T17:01:24.870+0000] {subprocess.py:93} INFO -   File "/home/***/.local/lib/python3.8/site-packages/sqlalchemy/engine/base.py", line 3371, in _wrap_pool_connect
[2025-07-07T17:01:24.871+0000] {subprocess.py:93} INFO -     return fn()
[2025-07-07T17:01:24.872+0000] {subprocess.py:93} INFO -   File "/home/***/.local/lib/python3.8/site-packages/sqlalchemy/pool/base.py", line 327, in connect
[2025-07-07T17:01:24.872+0000] {subprocess.py:93} INFO -     return _ConnectionFairy._checkout(self)
[2025-07-07T17:01:24.873+0000] {subprocess.py:93} INFO -   File "/home/***/.local/lib/python3.8/site-packages/sqlalchemy/pool/base.py", line 894, in _checkout
[2025-07-07T17:01:24.873+0000] {subprocess.py:93} INFO -     fairy = _ConnectionRecord.checkout(pool)
[2025-07-07T17:01:24.874+0000] {subprocess.py:93} INFO -   File "/home/***/.local/lib/python3.8/site-packages/sqlalchemy/pool/base.py", line 493, in checkout
[2025-07-07T17:01:24.875+0000] {subprocess.py:93} INFO -     rec = pool._do_get()
[2025-07-07T17:01:24.875+0000] {subprocess.py:93} INFO -   File "/home/***/.local/lib/python3.8/site-packages/sqlalchemy/pool/impl.py", line 146, in _do_get
[2025-07-07T17:01:24.875+0000] {subprocess.py:93} INFO -     self._dec_overflow()
[2025-07-07T17:01:24.876+0000] {subprocess.py:93} INFO -   File "/home/***/.local/lib/python3.8/site-packages/sqlalchemy/util/langhelpers.py", line 70, in __exit__
[2025-07-07T17:01:24.877+0000] {subprocess.py:93} INFO -     compat.raise_(
[2025-07-07T17:01:24.877+0000] {subprocess.py:93} INFO -   File "/home/***/.local/lib/python3.8/site-packages/sqlalchemy/util/compat.py", line 211, in raise_
[2025-07-07T17:01:24.877+0000] {subprocess.py:93} INFO -     raise exception
[2025-07-07T17:01:24.878+0000] {subprocess.py:93} INFO -   File "/home/***/.local/lib/python3.8/site-packages/sqlalchemy/pool/impl.py", line 143, in _do_get
[2025-07-07T17:01:24.878+0000] {subprocess.py:93} INFO -     return self._create_connection()
[2025-07-07T17:01:24.879+0000] {subprocess.py:93} INFO -   File "/home/***/.local/lib/python3.8/site-packages/sqlalchemy/pool/base.py", line 273, in _create_connection
[2025-07-07T17:01:24.880+0000] {subprocess.py:93} INFO -     return _ConnectionRecord(self)
[2025-07-07T17:01:24.880+0000] {subprocess.py:93} INFO -   File "/home/***/.local/lib/python3.8/site-packages/sqlalchemy/pool/base.py", line 388, in __init__
[2025-07-07T17:01:24.881+0000] {subprocess.py:93} INFO -     self.__connect()
[2025-07-07T17:01:24.881+0000] {subprocess.py:93} INFO -   File "/home/***/.local/lib/python3.8/site-packages/sqlalchemy/pool/base.py", line 691, in __connect
[2025-07-07T17:01:24.882+0000] {subprocess.py:93} INFO -     pool.logger.debug("Error on connect(): %s", e)
[2025-07-07T17:01:24.882+0000] {subprocess.py:93} INFO -   File "/home/***/.local/lib/python3.8/site-packages/sqlalchemy/util/langhelpers.py", line 70, in __exit__
[2025-07-07T17:01:24.883+0000] {subprocess.py:93} INFO -     compat.raise_(
[2025-07-07T17:01:24.883+0000] {subprocess.py:93} INFO -   File "/home/***/.local/lib/python3.8/site-packages/sqlalchemy/util/compat.py", line 211, in raise_
[2025-07-07T17:01:24.884+0000] {subprocess.py:93} INFO -     raise exception
[2025-07-07T17:01:24.884+0000] {subprocess.py:93} INFO -   File "/home/***/.local/lib/python3.8/site-packages/sqlalchemy/pool/base.py", line 686, in __connect
[2025-07-07T17:01:24.885+0000] {subprocess.py:93} INFO -     self.dbapi_connection = connection = pool._invoke_creator(self)
[2025-07-07T17:01:24.885+0000] {subprocess.py:93} INFO -   File "/home/***/.local/lib/python3.8/site-packages/sqlalchemy/engine/create.py", line 574, in connect
[2025-07-07T17:01:24.886+0000] {subprocess.py:93} INFO -     return dialect.connect(*cargs, **cparams)
[2025-07-07T17:01:24.886+0000] {subprocess.py:93} INFO -   File "/home/***/.local/lib/python3.8/site-packages/sqlalchemy/engine/default.py", line 598, in connect
[2025-07-07T17:01:24.887+0000] {subprocess.py:93} INFO -     return self.dbapi.connect(*cargs, **cparams)
[2025-07-07T17:01:24.887+0000] {subprocess.py:93} INFO -   File "/home/***/.local/lib/python3.8/site-packages/psycopg2/__init__.py", line 122, in connect
[2025-07-07T17:01:24.888+0000] {subprocess.py:93} INFO -     conn = _connect(dsn, connection_factory=connection_factory, **kwasync)
[2025-07-07T17:01:24.888+0000] {subprocess.py:93} INFO - sqlalchemy.exc.OperationalError: (psycopg2.OperationalError) connection to server at "postgres" (172.21.0.4), port 5432 failed: FATAL:  database "ny_sub_turnstiles" does not exist
[2025-07-07T17:01:24.889+0000] {subprocess.py:93} INFO - 
[2025-07-07T17:01:24.890+0000] {subprocess.py:93} INFO - (Background on this error at: https://sqlalche.me/e/14/e3q8)
[2025-07-07T17:01:24.943+0000] {subprocess.py:97} INFO - Command exited with return code 1
[2025-07-07T17:01:24.956+0000] {taskinstance.py:1937} ERROR - Task failed with exception
Traceback (most recent call last):
  File "/home/airflow/.local/lib/python3.8/site-packages/airflow/operators/bash.py", line 210, in execute
    raise AirflowException(
airflow.exceptions.AirflowException: Bash command failed. The command returned a non-zero exit code 1.
[2025-07-07T17:01:24.960+0000] {taskinstance.py:1400} INFO - Marking task as FAILED. dag_id=turnstile_ml_pipeline, task_id=download_and_ingest, execution_date=20250707T170102, start_date=20250707T170110, end_date=20250707T170124
[2025-07-07T17:01:24.974+0000] {standard_task_runner.py:104} ERROR - Failed to execute job 21 for task download_and_ingest (Bash command failed. The command returned a non-zero exit code 1.; 53)
[2025-07-07T17:01:24.995+0000] {local_task_job_runner.py:228} INFO - Task exited with return code 1
[2025-07-07T17:01:25.024+0000] {taskinstance.py:2778} INFO - 0 downstream tasks scheduled from follow-on schedule check
