[2025-07-13T16:18:33.030+0000] {local_task_job_runner.py:123} INFO - ::group::Pre task execution logs
[2025-07-13T16:18:33.062+0000] {taskinstance.py:2614} INFO - Dependencies all met for dep_context=non-requeueable deps ti=<TaskInstance: turnstile_ml_pipeline.tune_model manual__2025-07-13T16:17:25+00:00 [queued]>
[2025-07-13T16:18:33.078+0000] {taskinstance.py:2614} INFO - Dependencies all met for dep_context=requeueable deps ti=<TaskInstance: turnstile_ml_pipeline.tune_model manual__2025-07-13T16:17:25+00:00 [queued]>
[2025-07-13T16:18:33.079+0000] {taskinstance.py:2867} INFO - Starting attempt 1 of 1
[2025-07-13T16:18:33.104+0000] {taskinstance.py:2890} INFO - Executing <Task(BashOperator): tune_model> on 2025-07-13 16:17:25+00:00
[2025-07-13T16:18:33.122+0000] {logging_mixin.py:190} WARNING - /home/***/.local/lib/python3.12/site-packages/***/task/task_runner/standard_task_runner.py:70 DeprecationWarning: This process (pid=183) is multi-threaded, use of fork() may lead to deadlocks in the child.
[2025-07-13T16:18:33.125+0000] {standard_task_runner.py:72} INFO - Started process 191 to run task
[2025-07-13T16:18:33.123+0000] {standard_task_runner.py:104} INFO - Running: ['***', 'tasks', 'run', 'turnstile_ml_pipeline', 'tune_model', 'manual__2025-07-13T16:17:25+00:00', '--job-id', '7', '--raw', '--subdir', 'DAGS_FOLDER/pipeline_dag.py', '--cfg-path', '/tmp/tmpld4b0cs1']
[2025-07-13T16:18:33.127+0000] {standard_task_runner.py:105} INFO - Job 7: Subtask tune_model
[2025-07-13T16:18:33.151+0000] {logging_mixin.py:190} WARNING - /home/***/.local/lib/python3.12/site-packages/***/settings.py:209 DeprecationWarning: The sql_alchemy_conn option in [core] has been moved to the sql_alchemy_conn option in [database] - the old setting has been used, but please update your config.
[2025-07-13T16:18:33.215+0000] {task_command.py:467} INFO - Running <TaskInstance: turnstile_ml_pipeline.tune_model manual__2025-07-13T16:17:25+00:00 [running]> on host 6011aa489c7f
[2025-07-13T16:18:33.353+0000] {taskinstance.py:3134} INFO - Exporting env vars: AIRFLOW_CTX_DAG_OWNER='***' AIRFLOW_CTX_DAG_ID='turnstile_ml_pipeline' AIRFLOW_CTX_TASK_ID='tune_model' AIRFLOW_CTX_EXECUTION_DATE='2025-07-13T16:17:25+00:00' AIRFLOW_CTX_TRY_NUMBER='1' AIRFLOW_CTX_DAG_RUN_ID='manual__2025-07-13T16:17:25+00:00'
[2025-07-13T16:18:33.354+0000] {taskinstance.py:732} INFO - ::endgroup::
[2025-07-13T16:18:33.385+0000] {subprocess.py:78} INFO - Tmp dir root location: /tmp
[2025-07-13T16:18:33.387+0000] {subprocess.py:88} INFO - Running command: ['/usr/bin/bash', '-c', '\n            python /opt/***/pipeline/tune_model.py                 --user ***                 --password ***                 --host postgres                 --port 5432                 --db_name ny_sub_turnstiles                 --features_table turnstile_features         ']
[2025-07-13T16:18:33.404+0000] {subprocess.py:99} INFO - Output:
[2025-07-13T16:18:39.092+0000] {subprocess.py:106} INFO -   0%|          | 0/30 [00:00<?, ?trial/s, best loss=?]2025/07/13 16:18:39 WARNING mlflow.utils.git_utils: Failed to import Git (the Git executable is probably not on your PATH), so Git SHA is not available. Error: Failed to initialize: Bad git executable.
[2025-07-13T16:18:39.094+0000] {subprocess.py:106} INFO - The git executable must be specified in one of the following ways:
[2025-07-13T16:18:39.095+0000] {subprocess.py:106} INFO -     - be included in your $PATH
[2025-07-13T16:18:39.096+0000] {subprocess.py:106} INFO -     - be set via $GIT_PYTHON_GIT_EXECUTABLE
[2025-07-13T16:18:39.097+0000] {subprocess.py:106} INFO -     - explicitly set via git.refresh(<full-path-to-git-executable>)
[2025-07-13T16:18:39.097+0000] {subprocess.py:106} INFO - 
[2025-07-13T16:18:39.098+0000] {subprocess.py:106} INFO - All git commands will error until this is rectified.
[2025-07-13T16:18:39.099+0000] {subprocess.py:106} INFO - 
[2025-07-13T16:18:39.100+0000] {subprocess.py:106} INFO - This initial message can be silenced or aggravated in the future by setting the
[2025-07-13T16:18:39.100+0000] {subprocess.py:106} INFO - $GIT_PYTHON_REFRESH environment variable. Use one of the following values:
[2025-07-13T16:18:39.101+0000] {subprocess.py:106} INFO -     - quiet|q|silence|s|silent|none|n|0: for no message or exception
[2025-07-13T16:18:39.102+0000] {subprocess.py:106} INFO -     - warn|w|warning|log|l|1: for a warning message (logging level CRITICAL, displayed by default)
[2025-07-13T16:18:39.103+0000] {subprocess.py:106} INFO -     - error|e|exception|raise|r|2: for a raised exception
[2025-07-13T16:18:39.104+0000] {subprocess.py:106} INFO - 
[2025-07-13T16:18:39.104+0000] {subprocess.py:106} INFO - Example:
[2025-07-13T16:18:39.105+0000] {subprocess.py:106} INFO -     export GIT_PYTHON_REFRESH=quiet
[2025-07-13T16:18:39.106+0000] {subprocess.py:106} INFO - 
[2025-07-13T16:18:39.107+0000] {subprocess.py:106} INFO - 
[2025-07-13T16:18:41.182+0000] {subprocess.py:106} INFO -                                                       üèÉ View run tune-20250713-161838 at: http://mlflow:5000/#/experiments/1/runs/10eb7ed4cbd241808e65edf9ec3a7dcd
[2025-07-13T16:18:41.184+0000] {subprocess.py:106} INFO - 
[2025-07-13T16:18:41.185+0000] {subprocess.py:106} INFO -   0%|          | 0/30 [00:02<?, ?trial/s, best loss=?]                                                      üß™ View experiment at: http://mlflow:5000/#/experiments/1
[2025-07-13T16:18:41.186+0000] {subprocess.py:106} INFO - 
[2025-07-13T16:18:41.266+0000] {subprocess.py:106} INFO -   0%|          | 0/30 [00:02<?, ?trial/s, best loss=?]job exception: Experimental support for categorical data is not implemented for current tree method yet.
[2025-07-13T16:18:41.267+0000] {subprocess.py:106} INFO - 
[2025-07-13T16:18:41.268+0000] {subprocess.py:106} INFO -   0%|          | 0/30 [00:02<?, ?trial/s, best loss=?]
[2025-07-13T16:18:41.269+0000] {subprocess.py:106} INFO - Traceback (most recent call last):
[2025-07-13T16:18:41.270+0000] {subprocess.py:106} INFO -   File "/opt/***/pipeline/tune_model.py", line 117, in <module>
[2025-07-13T16:18:41.272+0000] {subprocess.py:106} INFO -     tune(df, args.experiment_name, args.run_prefix, args.n_trials)
[2025-07-13T16:18:41.273+0000] {subprocess.py:106} INFO -   File "/opt/***/pipeline/tune_model.py", line 76, in tune
[2025-07-13T16:18:41.277+0000] {subprocess.py:106} INFO -     best_result = fmin(
[2025-07-13T16:18:41.278+0000] {subprocess.py:106} INFO -                   ^^^^^
[2025-07-13T16:18:41.280+0000] {subprocess.py:106} INFO -   File "/home/***/.local/lib/python3.12/site-packages/hyperopt/fmin.py", line 540, in fmin
[2025-07-13T16:18:41.281+0000] {subprocess.py:106} INFO -     return trials.fmin(
[2025-07-13T16:18:41.282+0000] {subprocess.py:106} INFO -            ^^^^^^^^^^^^
[2025-07-13T16:18:41.283+0000] {subprocess.py:106} INFO -   File "/home/***/.local/lib/python3.12/site-packages/hyperopt/base.py", line 671, in fmin
[2025-07-13T16:18:41.285+0000] {subprocess.py:106} INFO -     return fmin(
[2025-07-13T16:18:41.287+0000] {subprocess.py:106} INFO -            ^^^^^
[2025-07-13T16:18:41.288+0000] {subprocess.py:106} INFO -   File "/home/***/.local/lib/python3.12/site-packages/hyperopt/fmin.py", line 586, in fmin
[2025-07-13T16:18:41.289+0000] {subprocess.py:106} INFO -     rval.exhaust()
[2025-07-13T16:18:41.290+0000] {subprocess.py:106} INFO -   File "/home/***/.local/lib/python3.12/site-packages/hyperopt/fmin.py", line 364, in exhaust
[2025-07-13T16:18:41.291+0000] {subprocess.py:106} INFO -     self.run(self.max_evals - n_done, block_until_done=self.asynchronous)
[2025-07-13T16:18:41.292+0000] {subprocess.py:106} INFO -   File "/home/***/.local/lib/python3.12/site-packages/hyperopt/fmin.py", line 300, in run
[2025-07-13T16:18:41.293+0000] {subprocess.py:106} INFO -     self.serial_evaluate()
[2025-07-13T16:18:41.294+0000] {subprocess.py:106} INFO -   File "/home/***/.local/lib/python3.12/site-packages/hyperopt/fmin.py", line 178, in serial_evaluate
[2025-07-13T16:18:41.295+0000] {subprocess.py:106} INFO -     result = self.domain.evaluate(spec, ctrl)
[2025-07-13T16:18:41.296+0000] {subprocess.py:106} INFO -              ^^^^^^^^^^^^^^^^^^^^^^^^^^^^^^^^
[2025-07-13T16:18:41.297+0000] {subprocess.py:106} INFO -   File "/home/***/.local/lib/python3.12/site-packages/hyperopt/base.py", line 892, in evaluate
[2025-07-13T16:18:41.298+0000] {subprocess.py:106} INFO -     rval = self.fn(pyll_rval)
[2025-07-13T16:18:41.299+0000] {subprocess.py:106} INFO -            ^^^^^^^^^^^^^^^^^^
[2025-07-13T16:18:41.301+0000] {subprocess.py:106} INFO -   File "/opt/***/pipeline/tune_model.py", line 65, in objective
[2025-07-13T16:18:41.302+0000] {subprocess.py:106} INFO -     model.fit(X_train, y_train)
[2025-07-13T16:18:41.304+0000] {subprocess.py:106} INFO -   File "/home/***/.local/lib/python3.12/site-packages/xgboost/core.py", line 620, in inner_f
[2025-07-13T16:18:41.305+0000] {subprocess.py:106} INFO -     return func(**kwargs)
[2025-07-13T16:18:41.306+0000] {subprocess.py:106} INFO -            ^^^^^^^^^^^^^^
[2025-07-13T16:18:41.307+0000] {subprocess.py:106} INFO -   File "/home/***/.local/lib/python3.12/site-packages/xgboost/sklearn.py", line 1022, in fit
[2025-07-13T16:18:41.309+0000] {subprocess.py:106} INFO -     ) = self._configure_fit(
[2025-07-13T16:18:41.310+0000] {subprocess.py:106} INFO -         ^^^^^^^^^^^^^^^^^^^^
[2025-07-13T16:18:41.311+0000] {subprocess.py:106} INFO -   File "/home/***/.local/lib/python3.12/site-packages/xgboost/sklearn.py", line 892, in _configure_fit
[2025-07-13T16:18:41.312+0000] {subprocess.py:106} INFO -     raise ValueError(
[2025-07-13T16:18:41.313+0000] {subprocess.py:106} INFO - ValueError: Experimental support for categorical data is not implemented for current tree method yet.
[2025-07-13T16:18:41.867+0000] {subprocess.py:110} INFO - Command exited with return code 1
[2025-07-13T16:18:41.899+0000] {taskinstance.py:3313} ERROR - Task failed with exception
Traceback (most recent call last):
  File "/home/airflow/.local/lib/python3.12/site-packages/airflow/models/taskinstance.py", line 768, in _execute_task
    result = _execute_callable(context=context, **execute_callable_kwargs)
             ^^^^^^^^^^^^^^^^^^^^^^^^^^^^^^^^^^^^^^^^^^^^^^^^^^^^^^^^^^^^^
  File "/home/airflow/.local/lib/python3.12/site-packages/airflow/models/taskinstance.py", line 734, in _execute_callable
    return ExecutionCallableRunner(
           ^^^^^^^^^^^^^^^^^^^^^^^^
  File "/home/airflow/.local/lib/python3.12/site-packages/airflow/utils/operator_helpers.py", line 252, in run
    return self.func(*args, **kwargs)
           ^^^^^^^^^^^^^^^^^^^^^^^^^^
  File "/home/airflow/.local/lib/python3.12/site-packages/airflow/models/baseoperator.py", line 424, in wrapper
    return func(self, *args, **kwargs)
           ^^^^^^^^^^^^^^^^^^^^^^^^^^^
  File "/home/airflow/.local/lib/python3.12/site-packages/airflow/operators/bash.py", line 276, in execute
    raise AirflowException(
airflow.exceptions.AirflowException: Bash command failed. The command returned a non-zero exit code 1.
[2025-07-13T16:18:41.907+0000] {taskinstance.py:1226} INFO - Marking task as FAILED. dag_id=turnstile_ml_pipeline, task_id=tune_model, run_id=manual__2025-07-13T16:17:25+00:00, execution_date=20250713T161725, start_date=20250713T161833, end_date=20250713T161841
[2025-07-13T16:18:41.963+0000] {taskinstance.py:341} INFO - ::group::Post task execution logs
[2025-07-13T16:18:41.966+0000] {standard_task_runner.py:124} ERROR - Failed to execute job 7 for task tune_model (Bash command failed. The command returned a non-zero exit code 1.; 191)
Traceback (most recent call last):
  File "/home/airflow/.local/lib/python3.12/site-packages/airflow/task/task_runner/standard_task_runner.py", line 117, in _start_by_fork
    ret = args.func(args, dag=self.dag)
          ^^^^^^^^^^^^^^^^^^^^^^^^^^^^^
  File "/home/airflow/.local/lib/python3.12/site-packages/airflow/cli/cli_config.py", line 49, in command
    return func(*args, **kwargs)
           ^^^^^^^^^^^^^^^^^^^^^
  File "/home/airflow/.local/lib/python3.12/site-packages/airflow/utils/cli.py", line 116, in wrapper
    return f(*args, **kwargs)
           ^^^^^^^^^^^^^^^^^^
  File "/home/airflow/.local/lib/python3.12/site-packages/airflow/cli/commands/task_command.py", line 483, in task_run
    task_return_code = _run_task_by_selected_method(args, _dag, ti)
                       ^^^^^^^^^^^^^^^^^^^^^^^^^^^^^^^^^^^^^^^^^^^^
  File "/home/airflow/.local/lib/python3.12/site-packages/airflow/cli/commands/task_command.py", line 256, in _run_task_by_selected_method
    return _run_raw_task(args, ti)
           ^^^^^^^^^^^^^^^^^^^^^^^
  File "/home/airflow/.local/lib/python3.12/site-packages/airflow/cli/commands/task_command.py", line 341, in _run_raw_task
    return ti._run_raw_task(
           ^^^^^^^^^^^^^^^^^
  File "/home/airflow/.local/lib/python3.12/site-packages/airflow/utils/session.py", line 97, in wrapper
    return func(*args, session=session, **kwargs)
           ^^^^^^^^^^^^^^^^^^^^^^^^^^^^^^^^^^^^^^
  File "/home/airflow/.local/lib/python3.12/site-packages/airflow/models/taskinstance.py", line 3006, in _run_raw_task
    return _run_raw_task(
           ^^^^^^^^^^^^^^
  File "/home/airflow/.local/lib/python3.12/site-packages/airflow/models/taskinstance.py", line 274, in _run_raw_task
    TaskInstance._execute_task_with_callbacks(
  File "/home/airflow/.local/lib/python3.12/site-packages/airflow/models/taskinstance.py", line 3161, in _execute_task_with_callbacks
    result = self._execute_task(context, task_orig)
             ^^^^^^^^^^^^^^^^^^^^^^^^^^^^^^^^^^^^^^
  File "/home/airflow/.local/lib/python3.12/site-packages/airflow/models/taskinstance.py", line 3185, in _execute_task
    return _execute_task(self, context, task_orig)
           ^^^^^^^^^^^^^^^^^^^^^^^^^^^^^^^^^^^^^^^
  File "/home/airflow/.local/lib/python3.12/site-packages/airflow/models/taskinstance.py", line 768, in _execute_task
    result = _execute_callable(context=context, **execute_callable_kwargs)
             ^^^^^^^^^^^^^^^^^^^^^^^^^^^^^^^^^^^^^^^^^^^^^^^^^^^^^^^^^^^^^
  File "/home/airflow/.local/lib/python3.12/site-packages/airflow/models/taskinstance.py", line 734, in _execute_callable
    return ExecutionCallableRunner(
           ^^^^^^^^^^^^^^^^^^^^^^^^
  File "/home/airflow/.local/lib/python3.12/site-packages/airflow/utils/operator_helpers.py", line 252, in run
    return self.func(*args, **kwargs)
           ^^^^^^^^^^^^^^^^^^^^^^^^^^
  File "/home/airflow/.local/lib/python3.12/site-packages/airflow/models/baseoperator.py", line 424, in wrapper
    return func(self, *args, **kwargs)
           ^^^^^^^^^^^^^^^^^^^^^^^^^^^
  File "/home/airflow/.local/lib/python3.12/site-packages/airflow/operators/bash.py", line 276, in execute
    raise AirflowException(
airflow.exceptions.AirflowException: Bash command failed. The command returned a non-zero exit code 1.
[2025-07-13T16:18:42.017+0000] {local_task_job_runner.py:266} INFO - Task exited with return code 1
[2025-07-13T16:18:42.054+0000] {taskinstance.py:3901} INFO - 0 downstream tasks scheduled from follow-on schedule check
[2025-07-13T16:18:42.063+0000] {local_task_job_runner.py:245} INFO - ::endgroup::
